Workbook
Name Employees: Billing!XEZ1:XFA999
Name Employees: Timesheet!XEZ1:XFA999

Sheet Week 1 Roster
A1: Employee ID | B1: Store | C1: Preferred Name | D1: 45831 | E1: =TEXT(D1,"dddd") -> Monday | F1: =IF(ISNUMBER(MATCH(D1,'Public Holidays'!$A:$A,0)),"Pub",IF(WEEKDAY(D1,2)=7,"Sun",IF(WEEKDAY(D1,2)=6,"Sat","Ord"))) -> Ord | G1: =D1+1 -> 45832 | H1: =TEXT(G1,"dddd") -> Tuesday | I1: =IF(ISNUMBER(MATCH(G1,'Public Holidays'!$A:$A,0)),"Pub",IF(WEEKDAY(G1,2)=7,"Sun",IF(WEEKDAY(G1,2)=6,"Sat","Ord"))) -> Ord | J1: =G1+1 -> 45833 | K1: =TEXT(J1,"dddd") -> Wednesday | L1: =IF(ISNUMBER(MATCH(J1,'Public Holidays'!$A:$A,0)),"Pub",IF(WEEKDAY(J1,2)=7,"Sun",IF(WEEKDAY(J1,2)=6,"Sat","Ord"))) -> Ord | M1: =J1+1 -> 45834 | N1: =TEXT(M1,"dddd") -> Thursday | O1: =IF(ISNUMBER(MATCH(M1,'Public Holidays'!$A:$A,0)),"Pub",IF(WEEKDAY(M1,2)=7,"Sun",IF(WEEKDAY(M1,2)=6,"Sat","Ord"))) -> Ord | P1: =M1+1 -> 45835 | Q1: =TEXT(P1,"dddd") -> Friday | R1: =IF(ISNUMBER(MATCH(P1,'Public Holidays'!$A:$A,0)),"Pub",IF(WEEKDAY(P1,2)=7,"Sun",IF(WEEKDAY(P1,2)=6,"Sat","Ord"))) -> Ord | S1: =P1+1 -> 45836 | T1: =TEXT(S1,"dddd") -> Saturday | U1: =IF(ISNUMBER(MATCH(S1,'Public Holidays'!$A:$A,0)),"Pub",IF(WEEKDAY(S1,2)=7,"Sun",IF(WEEKDAY(S1,2)=6,"Sat","Ord"))) -> Sat | V1: =S1+1 -> 45837 | W1: =TEXT(V1,"dddd") -> Sunday | X1: =IF(ISNUMBER(MATCH(V1,'Public Holidays'!$A:$A,0)),"Pub",IF(WEEKDAY(V1,2)=7,"Sun",IF(WEEKDAY(V1,2)=6,"Sat","Ord"))) -> Sun | Y1: =V1+1 -> 45838 | Z1: =TEXT(Y1,"dddd") -> Monday | AA1: =IF(ISNUMBER(MATCH(Y1,'Public Holidays'!$A:$A,0)),"Pub",IF(WEEKDAY(Y1,2)=7,"Sun",IF(WEEKDAY(Y1,2)=6,"Sat","Ord"))) -> Ord | AB1: Rostered Total | AD1: Add | AE1: Ord | AF1: Add | AG1: Sat | AH1: Add | AI1: Sun | AJ1: Add | AK1: Pub | AL1: Add | AM1: Eve 1 | AN1: Add | AO1: Eve 2 | AP1: No. of Shifts | AQ1: Personal Leave | AR1: Annual Leave | AS1: Unpaid Leave | AT1: Adjusted Total | AU1: Comment | AV1: 0.91666667 | AW1: 1 | AX1: 5.5 | AY1: 9 | AZ1: Employee ID | BA1: Dr1 | BB1: Br1 | BC1: =F1 -> Ord | BD1: =IF(BC1="Ord","Eve 1", BC1) -> Eve 1 | BE1: =IF(BH1="Ord","Eve 2",BH1) -> Eve 2 | BF1: Dr2 | BG1: Br2 | BH1: =I1 -> Ord | BI1: =IF(BH1="Ord","Eve 1", BH1) -> Eve 1 | BJ1: =IF(BM1="Ord","Eve 2",BM1) -> Eve 2 | BK1: Dr3 | BL1: Br3 | BM1: =L1 -> Ord | BN1: =IF(BM1="Ord","Eve 1", BM1) -> Eve 1 | BO1: =IF(BR1="Ord","Eve 2",BR1) -> Eve 2 | BP1: Dr4 | BQ1: Br4 | BR1: =O1 -> Ord | BS1: =IF(BR1="Ord","Eve 1", BR1) -> Eve 1 | BT1: =IF(BW1="Ord","Eve 2",BW1) -> Eve 2 | BU1: Dr5 | BV1: Br5 | BW1: =R1 -> Ord | BX1: =IF(BW1="Ord","Eve 1", BW1) -> Eve 1 | BY1: =IF(CB1="Ord","Eve 2",CB1) -> Sat | BZ1: Dr6 | CA1: Br6 | CB1: =U1 -> Sat | CC1: =IF(CB1="Ord","Eve 1", CB1) -> Sat | CD1: =IF(CG1="Ord","Eve 2",CG1) -> Sun | CE1: Dr7 | CF1: Br7 | CG1: =X1 -> Sun | CH1: =IF(CG1="Ord","Eve 1", CG1) -> Sun | CI1: =IF(CJ1="Ord","Eve 2",CJ1) -> Eve 2 | CJ1: =AA1 -> Ord | CK1: No. of Shifts
A2: =IF(ISNA(AZ2),"",AZ2) -> 10004 | B2: 501 | C2: Dan Yi | D2: 0.375 | E2: 0.70833333 | F2: =BA2-BB2 -> 7.5 | I2: =BF2-BG2 -> 0 | L2: =BK2-BL2 -> 0 | O2: =BP2-BQ2 -> 0 | R2: =BU2-BV2 -> 0 | U2: =BZ2-CA2 -> 0 | V2: 0.375 | W2: 0.70833333 | X2: =CE2-CF2 -> 7.5 | AB2: =SUM(F2,I2,L2,O2,R2,U2,X2) -> 15 | AE2: =SUMIF($BC$1:$CI$1,AE$1,$BC2:$CI2)+AD2 -> 7.5 | AG2: =SUMIF($BC$1:$CI$1,AG$1,$BC2:$CI2)+AF2 -> 0 | AI2: =SUMIF($BC$1:$CI$1,AI$1,$BC2:$CI2)+AH2 -> 7.5 | AK2: =SUMIF($BC$1:$CI$1,AK$1,$BC2:$CI2)+AJ2 -> 0 | AM2: =SUMIF($BC$1:$CI$1,AM$1,$BC2:$CI2)+AL2 -> 0 | AO2: =SUMIF($BC$1:$CI$1,AO$1,$BC2:$CI2)+AN2 -> 0 | AP2: =CK2 -> 2 | AT2: =AE2+AG2+AI2+AK2+AM2+AO2+SUM(AQ2:AS2) -> 15 | AZ2: =VLOOKUP(C2,Employees!D:I,6,FALSE) -> 10004 | BA2: =IF(ISBLANK(D2),0,(E2-D2)*24) -> 8 | BB2: =IF(BA2>$AY$1,1,IF(BA2>=$AX$1,0.5,0)) -> 0.5 | BC2: =BA2-BB2-BD2-BE2 -> 7.5 | BD2: =IF(AND(E2>$AV$1, D2<$AW$1),(MIN(E2,$AW$1)-MAX(D2,$AV$1))*24,0) -> 0 | BE2: =IF(E2>$AW$1,(E2-MAX(D2,$AW$1))*24,0) -> 0 | BF2: =IF(ISBLANK(G2),0,(H2-G2)*24) -> 0 | BG2: =IF(BF2>$AY$1,1,IF(BF2>=$AX$1,0.5,0)) -> 0 | BH2: =BF2-BG2-BI2-BJ2 -> 0 | BI2: =IF(AND(H2>$AV$1,G2<$AW$1),(MIN(H2,$AW$1)-MAX(G2,$AV$1))*24,0) -> 0 | BJ2: =IF(H2>$AW$1,(H2-MAX(G2,$AW$1))*24,0) -> 0 | BK2: =IF(ISBLANK(J2),0,(K2-J2)*24) -> 0 | BL2: =IF(BK2>$AY$1,1,IF(BK2>=$AX$1,0.5,0)) -> 0 | BM2: =BK2-BL2-BN2-BO2 -> 0 | BN2: =IF(AND(K2>$AV$1, J2<$AW$1),(MIN(K2,$AW$1)-MAX(J2,$AV$1))*24,0) -> 0 | BO2: =IF(K2>$AW$1,(K2-MAX(J2,$AW$1))*24,0) -> 0 | BP2: =IF(ISBLANK(M2),0,(N2-M2)*24) -> 0 | BQ2: =IF(BP2>$AY$1,1,IF(BP2>=$AX$1,0.5,0)) -> 0 | BR2: =BP2-BQ2-BS2-BT2 -> 0 | BS2: =IF(AND(N2>$AV$1, M2<$AW$1),(MIN(N2,$AW$1)-MAX(M2,$AV$1))*24,0) -> 0 | BT2: =IF(N2>$AW$1,(N2-MAX(M2,$AW$1))*24,0) -> 0 | BU2: =IF(ISBLANK(P2),0,(Q2-P2)*24) -> 0 | BV2: =IF(BU2>$AY$1,1,IF(BU2>=$AX$1,0.5,0)) -> 0 | BW2: =BU2-BV2-BX2-BY2 -> 0 | BX2: =IF(AND(Q2>$AV$1, P2<$AW$1),(MIN(Q2,$AW$1)-MAX(P2,$AV$1))*24,0) -> 0 | BY2: =IF(Q2>$AW$1,(Q2-MAX(P2,$AW$1))*24,0) -> 0 | BZ2: =IF(ISBLANK(S2),0,(T2-S2)*24) -> 0 | CA2: =IF(BZ2>$AY$1,1,IF(BZ2>=$AX$1,0.5,0)) -> 0 | CB2: =BZ2-CA2-CC2-CD2 -> 0 | CC2: =IF(AND(T2>$AV$1, S2<$AW$1),(MIN(T2,$AW$1)-MAX(S2,$AV$1))*24,0) -> 0 | CD2: =IF(T2>$AW$1,(T2-MAX(S2,$AW$1))*24,0) -> 0 | CE2: =IF(ISBLANK(V2),0,(W2-V2)*24) -> 8 | CF2: =IF(CE2>$AY$1,1,IF(CE2>=$AX$1,0.5,0)) -> 0.5 | CG2: =CE2-CF2-CH2-CI2 -> 7.5 | CH2: =IF(AND(W2>$AV$1, V2<$AW$1),(MIN(W2,$AW$1)-MAX(V2,$AV$1))*24,0) -> 0 | CI2: =IF(W2>$AW$1,(W2-MAX(V2,$AW$1))*24,0) -> 0 | CK2: =SUM(IF(F2>0,1,0),IF(I2>0,1,0),IF(L2>0,1,0),IF(O2>0,1,0),IF(R2>0,1,0),IF(U2>0,1,0),IF(X2>0,1,0)) -> 2
A3: =IF(ISNA(AZ3),"",AZ3) | F3: =BA3-BB3 -> 0 | I3: =BF3-BG3 -> 0 | L3: =BK3-BL3 -> 0 | O3: =BP3-BQ3 -> 0 | R3: =BU3-BV3 -> 0 | U3: =BZ3-CA3 -> 0 | X3: =CE3-CF3 -> 0 | AB3: =SUM(F3,I3,L3,O3,R3,U3,X3) -> 0 | AE3: =SUMIF($BC$1:$CI$1,AE$1,$BC3:$CI3)+AD3 -> 0 | AG3: =SUMIF($BC$1:$CI$1,AG$1,$BC3:$CI3)+AF3 -> 0 | AI3: =SUMIF($BC$1:$CI$1,AI$1,$BC3:$CI3)+AH3 -> 0 | AK3: =SUMIF($BC$1:$CI$1,AK$1,$BC3:$CI3)+AJ3 -> 0 | AM3: =SUMIF($BC$1:$CI$1,AM$1,$BC3:$CI3)+AL3 -> 0 | AO3: =SUMIF($BC$1:$CI$1,AO$1,$BC3:$CI3)+AN3 -> 0 | AP3: =CK3 -> 0 | AT3: =AE3+AG3+AI3+AK3+AM3+AO3+SUM(AQ3:AS3) -> 0 | AZ3: =VLOOKUP(C3,Employees!D:I,5,FALSE) -> #N/A | BA3: =IF(ISBLANK(D3),0,(E3-D3)*24) -> 0 | BB3: =IF(BA3>$AY$1,1,IF(BA3>=$AX$1,0.5,0)) -> 0 | BC3: =BA3-BB3-BD3-BE3 -> 0 | BD3: =IF(AND(E3>$AV$1, D3<$AW$1),(MIN(E3,$AW$1)-MAX(D3,$AV$1))*24,0) -> 0 | BE3: =IF(E3>$AW$1,(E3-MAX(D3,$AW$1))*24,0) -> 0 | BF3: =IF(ISBLANK(G3),0,(H3-G3)*24) -> 0 | BG3: =IF(BF3>$AY$1,1,IF(BF3>=$AX$1,0.5,0)) -> 0 | BH3: =BF3-BG3-BI3-BJ3 -> 0 | BI3: =IF(AND(H3>$AV$1,G3<$AW$1),(MIN(H3,$AW$1)-MAX(G3,$AV$1))*24,0) -> 0 | BJ3: =IF(H3>$AW$1,(H3-MAX(G3,$AW$1))*24,0) -> 0 | BK3: =IF(ISBLANK(J3),0,(K3-J3)*24) -> 0 | BL3: =IF(BK3>$AY$1,1,IF(BK3>=$AX$1,0.5,0)) -> 0 | BM3: =BK3-BL3-BN3-BO3 -> 0 | BN3: =IF(AND(K3>$AV$1, J3<$AW$1),(MIN(K3,$AW$1)-MAX(J3,$AV$1))*24,0) -> 0 | BO3: =IF(K3>$AW$1,(K3-MAX(J3,$AW$1))*24,0) -> 0 | BP3: =IF(ISBLANK(M3),0,(N3-M3)*24) -> 0 | BQ3: =IF(BP3>$AY$1,1,IF(BP3>=$AX$1,0.5,0)) -> 0 | BR3: =BP3-BQ3-BS3-BT3 -> 0 | BS3: =IF(AND(N3>$AV$1, M3<$AW$1),(MIN(N3,$AW$1)-MAX(M3,$AV$1))*24,0) -> 0 | BT3: =IF(N3>$AW$1,(N3-MAX(M3,$AW$1))*24,0) -> 0 | BU3: =IF(ISBLANK(P3),0,(Q3-P3)*24) -> 0 | BV3: =IF(BU3>$AY$1,1,IF(BU3>=$AX$1,0.5,0)) -> 0 | BW3: =BU3-BV3-BX3-BY3 -> 0 | BX3: =IF(AND(Q3>$AV$1, P3<$AW$1),(MIN(Q3,$AW$1)-MAX(P3,$AV$1))*24,0) -> 0 | BY3: =IF(Q3>$AW$1,(Q3-MAX(P3,$AW$1))*24,0) -> 0 | BZ3: =IF(ISBLANK(S3),0,(T3-S3)*24) -> 0 | CA3: =IF(BZ3>$AY$1,1,IF(BZ3>=$AX$1,0.5,0)) -> 0 | CB3: =BZ3-CA3-CC3-CD3 -> 0 | CC3: =IF(AND(T3>$AV$1, S3<$AW$1),(MIN(T3,$AW$1)-MAX(S3,$AV$1))*24,0) -> 0 | CD3: =IF(T3>$AW$1,(T3-MAX(S3,$AW$1))*24,0) -> 0 | CE3: =IF(ISBLANK(V3),0,(W3-V3)*24) -> 0 | CF3: =IF(CE3>$AY$1,1,IF(CE3>=$AX$1,0.5,0)) -> 0 | CG3: =CE3-CF3-CH3-CI3 -> 0 | CH3: =IF(AND(W3>$AV$1, V3<$AW$1),(MIN(W3,$AW$1)-MAX(V3,$AV$1))*24,0) -> 0 | CI3: =IF(W3>$AW$1,(W3-MAX(V3,$AW$1))*24,0) -> 0 | CK3: =SUM(IF(F3>0,1,0),IF(I3>0,1,0),IF(L3>0,1,0),IF(O3>0,1,0),IF(R3>0,1,0),IF(U3>0,1,0),IF(X3>0,1,0)) -> 0
A4: =IF(ISNA(AZ4),"",AZ4) | F4: =BA4-BB4 -> 0 | I4: =BF4-BG4 -> 0 | L4: =BK4-BL4 -> 0 | O4: =BP4-BQ4 -> 0 | R4: =BU4-BV4 -> 0 | U4: =BZ4-CA4 -> 0 | X4: =CE4-CF4 -> 0 | AB4: =SUM(F4,I4,L4,O4,R4,U4,X4) -> 0 | AE4: =SUMIF($BC$1:$CI$1,AE$1,$BC4:$CI4)+AD4 -> 0 | AG4: =SUMIF($BC$1:$CI$1,AG$1,$BC4:$CI4)+AF4 -> 0 | AI4: =SUMIF($BC$1:$CI$1,AI$1,$BC4:$CI4)+AH4 -> 0 | AK4: =SUMIF($BC$1:$CI$1,AK$1,$BC4:$CI4)+AJ4 -> 0 | AM4: =SUMIF($BC$1:$CI$1,AM$1,$BC4:$CI4)+AL4 -> 0 | AO4: =SUMIF($BC$1:$CI$1,AO$1,$BC4:$CI4)+AN4 -> 0 | AP4: =CK4 -> 0 | AT4: =AE4+AG4+AI4+AK4+AM4+AO4+SUM(AQ4:AS4) -> 0 | AZ4: =VLOOKUP(C4,Employees!D:I,5,FALSE) -> #N/A | BA4: =IF(ISBLANK(D4),0,(E4-D4)*24) -> 0 | BB4: =IF(BA4>$AY$1,1,IF(BA4>=$AX$1,0.5,0)) -> 0 | BC4: =BA4-BB4-BD4-BE4 -> 0 | BD4: =IF(AND(E4>$AV$1, D4<$AW$1),(MIN(E4,$AW$1)-MAX(D4,$AV$1))*24,0) -> 0 | BE4: =IF(E4>$AW$1,(E4-MAX(D4,$AW$1))*24,0) -> 0 | BF4: =IF(ISBLANK(G4),0,(H4-G4)*24) -> 0 | BG4: =IF(BF4>$AY$1,1,IF(BF4>=$AX$1,0.5,0)) -> 0 | BH4: =BF4-BG4-BI4-BJ4 -> 0 | BI4: =IF(AND(H4>$AV$1,G4<$AW$1),(MIN(H4,$AW$1)-MAX(G4,$AV$1))*24,0) -> 0 | BJ4: =IF(H4>$AW$1,(H4-MAX(G4,$AW$1))*24,0) -> 0 | BK4: =IF(ISBLANK(J4),0,(K4-J4)*24) -> 0 | BL4: =IF(BK4>$AY$1,1,IF(BK4>=$AX$1,0.5,0)) -> 0 | BM4: =BK4-BL4-BN4-BO4 -> 0 | BN4: =IF(AND(K4>$AV$1, J4<$AW$1),(MIN(K4,$AW$1)-MAX(J4,$AV$1))*24,0) -> 0 | BO4: =IF(K4>$AW$1,(K4-MAX(J4,$AW$1))*24,0) -> 0 | BP4: =IF(ISBLANK(M4),0,(N4-M4)*24) -> 0 | BQ4: =IF(BP4>$AY$1,1,IF(BP4>=$AX$1,0.5,0)) -> 0 | BR4: =BP4-BQ4-BS4-BT4 -> 0 | BS4: =IF(AND(N4>$AV$1, M4<$AW$1),(MIN(N4,$AW$1)-MAX(M4,$AV$1))*24,0) -> 0 | BT4: =IF(N4>$AW$1,(N4-MAX(M4,$AW$1))*24,0) -> 0 | BU4: =IF(ISBLANK(P4),0,(Q4-P4)*24) -> 0 | BV4: =IF(BU4>$AY$1,1,IF(BU4>=$AX$1,0.5,0)) -> 0 | BW4: =BU4-BV4-BX4-BY4 -> 0 | BX4: =IF(AND(Q4>$AV$1, P4<$AW$1),(MIN(Q4,$AW$1)-MAX(P4,$AV$1))*24,0) -> 0 | BY4: =IF(Q4>$AW$1,(Q4-MAX(P4,$AW$1))*24,0) -> 0 | BZ4: =IF(ISBLANK(S4),0,(T4-S4)*24) -> 0 | CA4: =IF(BZ4>$AY$1,1,IF(BZ4>=$AX$1,0.5,0)) -> 0 | CB4: =BZ4-CA4-CC4-CD4 -> 0 | CC4: =IF(AND(T4>$AV$1, S4<$AW$1),(MIN(T4,$AW$1)-MAX(S4,$AV$1))*24,0) -> 0 | CD4: =IF(T4>$AW$1,(T4-MAX(S4,$AW$1))*24,0) -> 0 | CE4: =IF(ISBLANK(V4),0,(W4-V4)*24) -> 0 | CF4: =IF(CE4>$AY$1,1,IF(CE4>=$AX$1,0.5,0)) -> 0 | CG4: =CE4-CF4-CH4-CI4 -> 0 | CH4: =IF(AND(W4>$AV$1, V4<$AW$1),(MIN(W4,$AW$1)-MAX(V4,$AV$1))*24,0) -> 0 | CI4: =IF(W4>$AW$1,(W4-MAX(V4,$AW$1))*24,0) -> 0 | CK4: =SUM(IF(F4>0,1,0),IF(I4>0,1,0),IF(L4>0,1,0),IF(O4>0,1,0),IF(R4>0,1,0),IF(U4>0,1,0),IF(X4>0,1,0)) -> 0
A5: =IF(ISNA(AZ5),"",AZ5) | F5: =BA5-BB5 -> 0 | I5: =BF5-BG5 -> 0 | L5: =BK5-BL5 -> 0 | O5: =BP5-BQ5 -> 0 | R5: =BU5-BV5 -> 0 | U5: =BZ5-CA5 -> 0 | X5: =CE5-CF5 -> 0 | AB5: =SUM(F5,I5,L5,O5,R5,U5,X5) -> 0 | AE5: =SUMIF($BC$1:$CI$1,AE$1,$BC5:$CI5)+AD5 -> 0 | AG5: =SUMIF($BC$1:$CI$1,AG$1,$BC5:$CI5)+AF5 -> 0 | AI5: =SUMIF($BC$1:$CI$1,AI$1,$BC5:$CI5)+AH5 -> 0 | AK5: =SUMIF($BC$1:$CI$1,AK$1,$BC5:$CI5)+AJ5 -> 0 | AM5: =SUMIF($BC$1:$CI$1,AM$1,$BC5:$CI5)+AL5 -> 0 | AO5: =SUMIF($BC$1:$CI$1,AO$1,$BC5:$CI5)+AN5 -> 0 | AP5: =CK5 -> 0 | AT5: =AE5+AG5+AI5+AK5+AM5+AO5+SUM(AQ5:AS5) -> 0 | AZ5: =VLOOKUP(C5,Employees!D:I,5,FALSE) -> #N/A | BA5: =IF(ISBLANK(D5),0,(E5-D5)*24) -> 0 | BB5: =IF(BA5>$AY$1,1,IF(BA5>=$AX$1,0.5,0)) -> 0 | BC5: =BA5-BB5-BD5-BE5 -> 0 | BD5: =IF(AND(E5>$AV$1, D5<$AW$1),(MIN(E5,$AW$1)-MAX(D5,$AV$1))*24,0) -> 0 | BE5: =IF(E5>$AW$1,(E5-MAX(D5,$AW$1))*24,0) -> 0 | BF5: =IF(ISBLANK(G5),0,(H5-G5)*24) -> 0 | BG5: =IF(BF5>$AY$1,1,IF(BF5>=$AX$1,0.5,0)) -> 0 | BH5: =BF5-BG5-BI5-BJ5 -> 0 | BI5: =IF(AND(H5>$AV$1,G5<$AW$1),(MIN(H5,$AW$1)-MAX(G5,$AV$1))*24,0) -> 0 | BJ5: =IF(H5>$AW$1,(H5-MAX(G5,$AW$1))*24,0) -> 0 | BK5: =IF(ISBLANK(J5),0,(K5-J5)*24) -> 0 | BL5: =IF(BK5>$AY$1,1,IF(BK5>=$AX$1,0.5,0)) -> 0 | BM5: =BK5-BL5-BN5-BO5 -> 0 | BN5: =IF(AND(K5>$AV$1, J5<$AW$1),(MIN(K5,$AW$1)-MAX(J5,$AV$1))*24,0) -> 0 | BO5: =IF(K5>$AW$1,(K5-MAX(J5,$AW$1))*24,0) -> 0 | BP5: =IF(ISBLANK(M5),0,(N5-M5)*24) -> 0 | BQ5: =IF(BP5>$AY$1,1,IF(BP5>=$AX$1,0.5,0)) -> 0 | BR5: =BP5-BQ5-BS5-BT5 -> 0 | BS5: =IF(AND(N5>$AV$1, M5<$AW$1),(MIN(N5,$AW$1)-MAX(M5,$AV$1))*24,0) -> 0 | BT5: =IF(N5>$AW$1,(N5-MAX(M5,$AW$1))*24,0) -> 0 | BU5: =IF(ISBLANK(P5),0,(Q5-P5)*24) -> 0 | BV5: =IF(BU5>$AY$1,1,IF(BU5>=$AX$1,0.5,0)) -> 0 | BW5: =BU5-BV5-BX5-BY5 -> 0 | BX5: =IF(AND(Q5>$AV$1, P5<$AW$1),(MIN(Q5,$AW$1)-MAX(P5,$AV$1))*24,0) -> 0 | BY5: =IF(Q5>$AW$1,(Q5-MAX(P5,$AW$1))*24,0) -> 0 | BZ5: =IF(ISBLANK(S5),0,(T5-S5)*24) -> 0 | CA5: =IF(BZ5>$AY$1,1,IF(BZ5>=$AX$1,0.5,0)) -> 0 | CB5: =BZ5-CA5-CC5-CD5 -> 0 | CC5: =IF(AND(T5>$AV$1, S5<$AW$1),(MIN(T5,$AW$1)-MAX(S5,$AV$1))*24,0) -> 0 | CD5: =IF(T5>$AW$1,(T5-MAX(S5,$AW$1))*24,0) -> 0 | CE5: =IF(ISBLANK(V5),0,(W5-V5)*24) -> 0 | CF5: =IF(CE5>$AY$1,1,IF(CE5>=$AX$1,0.5,0)) -> 0 | CG5: =CE5-CF5-CH5-CI5 -> 0 | CH5: =IF(AND(W5>$AV$1, V5<$AW$1),(MIN(W5,$AW$1)-MAX(V5,$AV$1))*24,0) -> 0 | CI5: =IF(W5>$AW$1,(W5-MAX(V5,$AW$1))*24,0) -> 0 | CK5: =SUM(IF(F5>0,1,0),IF(I5>0,1,0),IF(L5>0,1,0),IF(O5>0,1,0),IF(R5>0,1,0),IF(U5>0,1,0),IF(X5>0,1,0)) -> 0
A6: =IF(ISNA(AZ6),"",AZ6) | F6: =BA6-BB6 -> 0 | I6: =BF6-BG6 -> 0 | L6: =BK6-BL6 -> 0 | O6: =BP6-BQ6 -> 0 | R6: =BU6-BV6 -> 0 | U6: =BZ6-CA6 -> 0 | X6: =CE6-CF6 -> 0 | AB6: =SUM(F6,I6,L6,O6,R6,U6,X6) -> 0 | AE6: =SUMIF($BC$1:$CI$1,AE$1,$BC6:$CI6)+AD6 -> 0 | AG6: =SUMIF($BC$1:$CI$1,AG$1,$BC6:$CI6)+AF6 -> 0 | AI6: =SUMIF($BC$1:$CI$1,AI$1,$BC6:$CI6)+AH6 -> 0 | AK6: =SUMIF($BC$1:$CI$1,AK$1,$BC6:$CI6)+AJ6 -> 0 | AM6: =SUMIF($BC$1:$CI$1,AM$1,$BC6:$CI6)+AL6 -> 0 | AO6: =SUMIF($BC$1:$CI$1,AO$1,$BC6:$CI6)+AN6 -> 0 | AP6: =CK6 -> 0 | AT6: =AE6+AG6+AI6+AK6+AM6+AO6+SUM(AQ6:AS6) -> 0 | AZ6: =VLOOKUP(C6,Employees!D:I,5,FALSE) -> #N/A | BA6: =IF(ISBLANK(D6),0,(E6-D6)*24) -> 0 | BB6: =IF(BA6>$AY$1,1,IF(BA6>=$AX$1,0.5,0)) -> 0 | BC6: =BA6-BB6-BD6-BE6 -> 0 | BD6: =IF(AND(E6>$AV$1, D6<$AW$1),(MIN(E6,$AW$1)-MAX(D6,$AV$1))*24,0) -> 0 | BE6: =IF(E6>$AW$1,(E6-MAX(D6,$AW$1))*24,0) -> 0 | BF6: =IF(ISBLANK(G6),0,(H6-G6)*24) -> 0 | BG6: =IF(BF6>$AY$1,1,IF(BF6>=$AX$1,0.5,0)) -> 0 | BH6: =BF6-BG6-BI6-BJ6 -> 0 | BI6: =IF(AND(H6>$AV$1,G6<$AW$1),(MIN(H6,$AW$1)-MAX(G6,$AV$1))*24,0) -> 0 | BJ6: =IF(H6>$AW$1,(H6-MAX(G6,$AW$1))*24,0) -> 0 | BK6: =IF(ISBLANK(J6),0,(K6-J6)*24) -> 0 | BL6: =IF(BK6>$AY$1,1,IF(BK6>=$AX$1,0.5,0)) -> 0 | BM6: =BK6-BL6-BN6-BO6 -> 0 | BN6: =IF(AND(K6>$AV$1, J6<$AW$1),(MIN(K6,$AW$1)-MAX(J6,$AV$1))*24,0) -> 0 | BO6: =IF(K6>$AW$1,(K6-MAX(J6,$AW$1))*24,0) -> 0 | BP6: =IF(ISBLANK(M6),0,(N6-M6)*24) -> 0 | BQ6: =IF(BP6>$AY$1,1,IF(BP6>=$AX$1,0.5,0)) -> 0 | BR6: =BP6-BQ6-BS6-BT6 -> 0 | BS6: =IF(AND(N6>$AV$1, M6<$AW$1),(MIN(N6,$AW$1)-MAX(M6,$AV$1))*24,0) -> 0 | BT6: =IF(N6>$AW$1,(N6-MAX(M6,$AW$1))*24,0) -> 0 | BU6: =IF(ISBLANK(P6),0,(Q6-P6)*24) -> 0 | BV6: =IF(BU6>$AY$1,1,IF(BU6>=$AX$1,0.5,0)) -> 0 | BW6: =BU6-BV6-BX6-BY6 -> 0 | BX6: =IF(AND(Q6>$AV$1, P6<$AW$1),(MIN(Q6,$AW$1)-MAX(P6,$AV$1))*24,0) -> 0 | BY6: =IF(Q6>$AW$1,(Q6-MAX(P6,$AW$1))*24,0) -> 0 | BZ6: =IF(ISBLANK(S6),0,(T6-S6)*24) -> 0 | CA6: =IF(BZ6>$AY$1,1,IF(BZ6>=$AX$1,0.5,0)) -> 0 | CB6: =BZ6-CA6-CC6-CD6 -> 0 | CC6: =IF(AND(T6>$AV$1, S6<$AW$1),(MIN(T6,$AW$1)-MAX(S6,$AV$1))*24,0) -> 0 | CD6: =IF(T6>$AW$1,(T6-MAX(S6,$AW$1))*24,0) -> 0 | CE6: =IF(ISBLANK(V6),0,(W6-V6)*24) -> 0 | CF6: =IF(CE6>$AY$1,1,IF(CE6>=$AX$1,0.5,0)) -> 0 | CG6: =CE6-CF6-CH6-CI6 -> 0 | CH6: =IF(AND(W6>$AV$1, V6<$AW$1),(MIN(W6,$AW$1)-MAX(V6,$AV$1))*24,0) -> 0 | CI6: =IF(W6>$AW$1,(W6-MAX(V6,$AW$1))*24,0) -> 0 | CK6: =SUM(IF(F6>0,1,0),IF(I6>0,1,0),IF(L6>0,1,0),IF(O6>0,1,0),IF(R6>0,1,0),IF(U6>0,1,0),IF(X6>0,1,0)) -> 0
A7: =IF(ISNA(AZ7),"",AZ7) | F7: =BA7-BB7 -> 0 | I7: =BF7-BG7 -> 0 | L7: =BK7-BL7 -> 0 | O7: =BP7-BQ7 -> 0 | R7: =BU7-BV7 -> 0 | U7: =BZ7-CA7 -> 0 | X7: =CE7-CF7 -> 0 | AB7: =SUM(F7,I7,L7,O7,R7,U7,X7) -> 0 | AE7: =SUMIF($BC$1:$CI$1,AE$1,$BC7:$CI7)+AD7 -> 0 | AG7: =SUMIF($BC$1:$CI$1,AG$1,$BC7:$CI7)+AF7 -> 0 | AI7: =SUMIF($BC$1:$CI$1,AI$1,$BC7:$CI7)+AH7 -> 0 | AK7: =SUMIF($BC$1:$CI$1,AK$1,$BC7:$CI7)+AJ7 -> 0 | AM7: =SUMIF($BC$1:$CI$1,AM$1,$BC7:$CI7)+AL7 -> 0 | AO7: =SUMIF($BC$1:$CI$1,AO$1,$BC7:$CI7)+AN7 -> 0 | AP7: =CK7 -> 0 | AT7: =AE7+AG7+AI7+AK7+AM7+AO7+SUM(AQ7:AS7) -> 0 | AZ7: =VLOOKUP(C7,Employees!D:I,5,FALSE) -> #N/A | BA7: =IF(ISBLANK(D7),0,(E7-D7)*24) -> 0 | BB7: =IF(BA7>$AY$1,1,IF(BA7>=$AX$1,0.5,0)) -> 0 | BC7: =BA7-BB7-BD7-BE7 -> 0 | BD7: =IF(AND(E7>$AV$1, D7<$AW$1),(MIN(E7,$AW$1)-MAX(D7,$AV$1))*24,0) -> 0 | BE7: =IF(E7>$AW$1,(E7-MAX(D7,$AW$1))*24,0) -> 0 | BF7: =IF(ISBLANK(G7),0,(H7-G7)*24) -> 0 | BG7: =IF(BF7>$AY$1,1,IF(BF7>=$AX$1,0.5,0)) -> 0 | BH7: =BF7-BG7-BI7-BJ7 -> 0 | BI7: =IF(AND(H7>$AV$1,G7<$AW$1),(MIN(H7,$AW$1)-MAX(G7,$AV$1))*24,0) -> 0 | BJ7: =IF(H7>$AW$1,(H7-MAX(G7,$AW$1))*24,0) -> 0 | BK7: =IF(ISBLANK(J7),0,(K7-J7)*24) -> 0 | BL7: =IF(BK7>$AY$1,1,IF(BK7>=$AX$1,0.5,0)) -> 0 | BM7: =BK7-BL7-BN7-BO7 -> 0 | BN7: =IF(AND(K7>$AV$1, J7<$AW$1),(MIN(K7,$AW$1)-MAX(J7,$AV$1))*24,0) -> 0 | BO7: =IF(K7>$AW$1,(K7-MAX(J7,$AW$1))*24,0) -> 0 | BP7: =IF(ISBLANK(M7),0,(N7-M7)*24) -> 0 | BQ7: =IF(BP7>$AY$1,1,IF(BP7>=$AX$1,0.5,0)) -> 0 | BR7: =BP7-BQ7-BS7-BT7 -> 0 | BS7: =IF(AND(N7>$AV$1, M7<$AW$1),(MIN(N7,$AW$1)-MAX(M7,$AV$1))*24,0) -> 0 | BT7: =IF(N7>$AW$1,(N7-MAX(M7,$AW$1))*24,0) -> 0 | BU7: =IF(ISBLANK(P7),0,(Q7-P7)*24) -> 0 | BV7: =IF(BU7>$AY$1,1,IF(BU7>=$AX$1,0.5,0)) -> 0 | BW7: =BU7-BV7-BX7-BY7 -> 0 | BX7: =IF(AND(Q7>$AV$1, P7<$AW$1),(MIN(Q7,$AW$1)-MAX(P7,$AV$1))*24,0) -> 0 | BY7: =IF(Q7>$AW$1,(Q7-MAX(P7,$AW$1))*24,0) -> 0 | BZ7: =IF(ISBLANK(S7),0,(T7-S7)*24) -> 0 | CA7: =IF(BZ7>$AY$1,1,IF(BZ7>=$AX$1,0.5,0)) -> 0 | CB7: =BZ7-CA7-CC7-CD7 -> 0 | CC7: =IF(AND(T7>$AV$1, S7<$AW$1),(MIN(T7,$AW$1)-MAX(S7,$AV$1))*24,0) -> 0 | CD7: =IF(T7>$AW$1,(T7-MAX(S7,$AW$1))*24,0) -> 0 | CE7: =IF(ISBLANK(V7),0,(W7-V7)*24) -> 0 | CF7: =IF(CE7>$AY$1,1,IF(CE7>=$AX$1,0.5,0)) -> 0 | CG7: =CE7-CF7-CH7-CI7 -> 0 | CH7: =IF(AND(W7>$AV$1, V7<$AW$1),(MIN(W7,$AW$1)-MAX(V7,$AV$1))*24,0) -> 0 | CI7: =IF(W7>$AW$1,(W7-MAX(V7,$AW$1))*24,0) -> 0 | CK7: =SUM(IF(F7>0,1,0),IF(I7>0,1,0),IF(L7>0,1,0),IF(O7>0,1,0),IF(R7>0,1,0),IF(U7>0,1,0),IF(X7>0,1,0)) -> 0
A8: =IF(ISNA(AZ8),"",AZ8) | F8: =BA8-BB8 -> 0 | I8: =BF8-BG8 -> 0 | L8: =BK8-BL8 -> 0 | O8: =BP8-BQ8 -> 0 | R8: =BU8-BV8 -> 0 | U8: =BZ8-CA8 -> 0 | X8: =CE8-CF8 -> 0 | AB8: =SUM(F8,I8,L8,O8,R8,U8,X8) -> 0 | AE8: =SUMIF($BC$1:$CI$1,AE$1,$BC8:$CI8)+AD8 -> 0 | AG8: =SUMIF($BC$1:$CI$1,AG$1,$BC8:$CI8)+AF8 -> 0 | AI8: =SUMIF($BC$1:$CI$1,AI$1,$BC8:$CI8)+AH8 -> 0 | AK8: =SUMIF($BC$1:$CI$1,AK$1,$BC8:$CI8)+AJ8 -> 0 | AM8: =SUMIF($BC$1:$CI$1,AM$1,$BC8:$CI8)+AL8 -> 0 | AO8: =SUMIF($BC$1:$CI$1,AO$1,$BC8:$CI8)+AN8 -> 0 | AP8: =CK8 -> 0 | AT8: =AE8+AG8+AI8+AK8+AM8+AO8+SUM(AQ8:AS8) -> 0 | AZ8: =VLOOKUP(C8,Employees!D:I,5,FALSE) -> #N/A | BA8: =IF(ISBLANK(D8),0,(E8-D8)*24) -> 0 | BB8: =IF(BA8>$AY$1,1,IF(BA8>=$AX$1,0.5,0)) -> 0 | BC8: =BA8-BB8-BD8-BE8 -> 0 | BD8: =IF(AND(E8>$AV$1, D8<$AW$1),(MIN(E8,$AW$1)-MAX(D8,$AV$1))*24,0) -> 0 | BE8: =IF(E8>$AW$1,(E8-MAX(D8,$AW$1))*24,0) -> 0 | BF8: =IF(ISBLANK(G8),0,(H8-G8)*24) -> 0 | BG8: =IF(BF8>$AY$1,1,IF(BF8>=$AX$1,0.5,0)) -> 0 | BH8: =BF8-BG8-BI8-BJ8 -> 0 | BI8: =IF(AND(H8>$AV$1,G8<$AW$1),(MIN(H8,$AW$1)-MAX(G8,$AV$1))*24,0) -> 0 | BJ8: =IF(H8>$AW$1,(H8-MAX(G8,$AW$1))*24,0) -> 0 | BK8: =IF(ISBLANK(J8),0,(K8-J8)*24) -> 0 | BL8: =IF(BK8>$AY$1,1,IF(BK8>=$AX$1,0.5,0)) -> 0 | BM8: =BK8-BL8-BN8-BO8 -> 0 | BN8: =IF(AND(K8>$AV$1, J8<$AW$1),(MIN(K8,$AW$1)-MAX(J8,$AV$1))*24,0) -> 0 | BO8: =IF(K8>$AW$1,(K8-MAX(J8,$AW$1))*24,0) -> 0 | BP8: =IF(ISBLANK(M8),0,(N8-M8)*24) -> 0 | BQ8: =IF(BP8>$AY$1,1,IF(BP8>=$AX$1,0.5,0)) -> 0 | BR8: =BP8-BQ8-BS8-BT8 -> 0 | BS8: =IF(AND(N8>$AV$1, M8<$AW$1),(MIN(N8,$AW$1)-MAX(M8,$AV$1))*24,0) -> 0 | BT8: =IF(N8>$AW$1,(N8-MAX(M8,$AW$1))*24,0) -> 0 | BU8: =IF(ISBLANK(P8),0,(Q8-P8)*24) -> 0 | BV8: =IF(BU8>$AY$1,1,IF(BU8>=$AX$1,0.5,0)) -> 0 | BW8: =BU8-BV8-BX8-BY8 -> 0 | BX8: =IF(AND(Q8>$AV$1, P8<$AW$1),(MIN(Q8,$AW$1)-MAX(P8,$AV$1))*24,0) -> 0 | BY8: =IF(Q8>$AW$1,(Q8-MAX(P8,$AW$1))*24,0) -> 0 | BZ8: =IF(ISBLANK(S8),0,(T8-S8)*24) -> 0 | CA8: =IF(BZ8>$AY$1,1,IF(BZ8>=$AX$1,0.5,0)) -> 0 | CB8: =BZ8-CA8-CC8-CD8 -> 0 | CC8: =IF(AND(T8>$AV$1, S8<$AW$1),(MIN(T8,$AW$1)-MAX(S8,$AV$1))*24,0) -> 0 | CD8: =IF(T8>$AW$1,(T8-MAX(S8,$AW$1))*24,0) -> 0 | CE8: =IF(ISBLANK(V8),0,(W8-V8)*24) -> 0 | CF8: =IF(CE8>$AY$1,1,IF(CE8>=$AX$1,0.5,0)) -> 0 | CG8: =CE8-CF8-CH8-CI8 -> 0 | CH8: =IF(AND(W8>$AV$1, V8<$AW$1),(MIN(W8,$AW$1)-MAX(V8,$AV$1))*24,0) -> 0 | CI8: =IF(W8>$AW$1,(W8-MAX(V8,$AW$1))*24,0) -> 0 | CK8: =SUM(IF(F8>0,1,0),IF(I8>0,1,0),IF(L8>0,1,0),IF(O8>0,1,0),IF(R8>0,1,0),IF(U8>0,1,0),IF(X8>0,1,0)) -> 0
A9: =IF(ISNA(AZ9),"",AZ9) | F9: =BA9-BB9 -> 0 | I9: =BF9-BG9 -> 0 | L9: =BK9-BL9 -> 0 | O9: =BP9-BQ9 -> 0 | R9: =BU9-BV9 -> 0 | U9: =BZ9-CA9 -> 0 | X9: =CE9-CF9 -> 0 | AB9: =SUM(F9,I9,L9,O9,R9,U9,X9) -> 0 | AE9: =SUMIF($BC$1:$CI$1,AE$1,$BC9:$CI9)+AD9 -> 0 | AG9: =SUMIF($BC$1:$CI$1,AG$1,$BC9:$CI9)+AF9 -> 0 | AI9: =SUMIF($BC$1:$CI$1,AI$1,$BC9:$CI9)+AH9 -> 0 | AK9: =SUMIF($BC$1:$CI$1,AK$1,$BC9:$CI9)+AJ9 -> 0 | AM9: =SUMIF($BC$1:$CI$1,AM$1,$BC9:$CI9)+AL9 -> 0 | AO9: =SUMIF($BC$1:$CI$1,AO$1,$BC9:$CI9)+AN9 -> 0 | AP9: =CK9 -> 0 | AT9: =AE9+AG9+AI9+AK9+AM9+AO9+SUM(AQ9:AS9) -> 0 | AZ9: =VLOOKUP(C9,Employees!D:I,5,FALSE) -> #N/A | BA9: =IF(ISBLANK(D9),0,(E9-D9)*24) -> 0 | BB9: =IF(BA9>$AY$1,1,IF(BA9>=$AX$1,0.5,0)) -> 0 | BC9: =BA9-BB9-BD9-BE9 -> 0 | BD9: =IF(AND(E9>$AV$1, D9<$AW$1),(MIN(E9,$AW$1)-MAX(D9,$AV$1))*24,0) -> 0 | BE9: =IF(E9>$AW$1,(E9-MAX(D9,$AW$1))*24,0) -> 0 | BF9: =IF(ISBLANK(G9),0,(H9-G9)*24) -> 0 | BG9: =IF(BF9>$AY$1,1,IF(BF9>=$AX$1,0.5,0)) -> 0 | BH9: =BF9-BG9-BI9-BJ9 -> 0 | BI9: =IF(AND(H9>$AV$1,G9<$AW$1),(MIN(H9,$AW$1)-MAX(G9,$AV$1))*24,0) -> 0 | BJ9: =IF(H9>$AW$1,(H9-MAX(G9,$AW$1))*24,0) -> 0 | BK9: =IF(ISBLANK(J9),0,(K9-J9)*24) -> 0 | BL9: =IF(BK9>$AY$1,1,IF(BK9>=$AX$1,0.5,0)) -> 0 | BM9: =BK9-BL9-BN9-BO9 -> 0 | BN9: =IF(AND(K9>$AV$1, J9<$AW$1),(MIN(K9,$AW$1)-MAX(J9,$AV$1))*24,0) -> 0 | BO9: =IF(K9>$AW$1,(K9-MAX(J9,$AW$1))*24,0) -> 0 | BP9: =IF(ISBLANK(M9),0,(N9-M9)*24) -> 0 | BQ9: =IF(BP9>$AY$1,1,IF(BP9>=$AX$1,0.5,0)) -> 0 | BR9: =BP9-BQ9-BS9-BT9 -> 0 | BS9: =IF(AND(N9>$AV$1, M9<$AW$1),(MIN(N9,$AW$1)-MAX(M9,$AV$1))*24,0) -> 0 | BT9: =IF(N9>$AW$1,(N9-MAX(M9,$AW$1))*24,0) -> 0 | BU9: =IF(ISBLANK(P9),0,(Q9-P9)*24) -> 0 | BV9: =IF(BU9>$AY$1,1,IF(BU9>=$AX$1,0.5,0)) -> 0 | BW9: =BU9-BV9-BX9-BY9 -> 0 | BX9: =IF(AND(Q9>$AV$1, P9<$AW$1),(MIN(Q9,$AW$1)-MAX(P9,$AV$1))*24,0) -> 0 | BY9: =IF(Q9>$AW$1,(Q9-MAX(P9,$AW$1))*24,0) -> 0 | BZ9: =IF(ISBLANK(S9),0,(T9-S9)*24) -> 0 | CA9: =IF(BZ9>$AY$1,1,IF(BZ9>=$AX$1,0.5,0)) -> 0 | CB9: =BZ9-CA9-CC9-CD9 -> 0 | CC9: =IF(AND(T9>$AV$1, S9<$AW$1),(MIN(T9,$AW$1)-MAX(S9,$AV$1))*24,0) -> 0 | CD9: =IF(T9>$AW$1,(T9-MAX(S9,$AW$1))*24,0) -> 0 | CE9: =IF(ISBLANK(V9),0,(W9-V9)*24) -> 0 | CF9: =IF(CE9>$AY$1,1,IF(CE9>=$AX$1,0.5,0)) -> 0 | CG9: =CE9-CF9-CH9-CI9 -> 0 | CH9: =IF(AND(W9>$AV$1, V9<$AW$1),(MIN(W9,$AW$1)-MAX(V9,$AV$1))*24,0) -> 0 | CI9: =IF(W9>$AW$1,(W9-MAX(V9,$AW$1))*24,0) -> 0 | CK9: =SUM(IF(F9>0,1,0),IF(I9>0,1,0),IF(L9>0,1,0),IF(O9>0,1,0),IF(R9>0,1,0),IF(U9>0,1,0),IF(X9>0,1,0)) -> 0
A10: =IF(ISNA(AZ10),"",AZ10) | F10: =BA10-BB10 -> 0 | I10: =BF10-BG10 -> 0 | L10: =BK10-BL10 -> 0 | O10: =BP10-BQ10 -> 0 | R10: =BU10-BV10 -> 0 | U10: =BZ10-CA10 -> 0 | X10: =CE10-CF10 -> 0 | AB10: =SUM(F10,I10,L10,O10,R10,U10,X10) -> 0 | AE10: =SUMIF($BC$1:$CI$1,AE$1,$BC10:$CI10)+AD10 -> 0 | AG10: =SUMIF($BC$1:$CI$1,AG$1,$BC10:$CI10)+AF10 -> 0 | AI10: =SUMIF($BC$1:$CI$1,AI$1,$BC10:$CI10)+AH10 -> 0 | AK10: =SUMIF($BC$1:$CI$1,AK$1,$BC10:$CI10)+AJ10 -> 0 | AM10: =SUMIF($BC$1:$CI$1,AM$1,$BC10:$CI10)+AL10 -> 0 | AO10: =SUMIF($BC$1:$CI$1,AO$1,$BC10:$CI10)+AN10 -> 0 | AP10: =CK10 -> 0 | AT10: =AE10+AG10+AI10+AK10+AM10+AO10+SUM(AQ10:AS10) -> 0 | AZ10: =VLOOKUP(C10,Employees!D:I,5,FALSE) -> #N/A | BA10: =IF(ISBLANK(D10),0,(E10-D10)*24) -> 0 | BB10: =IF(BA10>$AY$1,1,IF(BA10>=$AX$1,0.5,0)) -> 0 | BC10: =BA10-BB10-BD10-BE10 -> 0 | BD10: =IF(AND(E10>$AV$1, D10<$AW$1),(MIN(E10,$AW$1)-MAX(D10,$AV$1))*24,0) -> 0 | BE10: =IF(E10>$AW$1,(E10-MAX(D10,$AW$1))*24,0) -> 0 | BF10: =IF(ISBLANK(G10),0,(H10-G10)*24) -> 0 | BG10: =IF(BF10>$AY$1,1,IF(BF10>=$AX$1,0.5,0)) -> 0 | BH10: =BF10-BG10-BI10-BJ10 -> 0 | BI10: =IF(AND(H10>$AV$1,G10<$AW$1),(MIN(H10,$AW$1)-MAX(G10,$AV$1))*24,0) -> 0 | BJ10: =IF(H10>$AW$1,(H10-MAX(G10,$AW$1))*24,0) -> 0 | BK10: =IF(ISBLANK(J10),0,(K10-J10)*24) -> 0 | BL10: =IF(BK10>$AY$1,1,IF(BK10>=$AX$1,0.5,0)) -> 0 | BM10: =BK10-BL10-BN10-BO10 -> 0 | BN10: =IF(AND(K10>$AV$1, J10<$AW$1),(MIN(K10,$AW$1)-MAX(J10,$AV$1))*24,0) -> 0 | BO10: =IF(K10>$AW$1,(K10-MAX(J10,$AW$1))*24,0) -> 0 | BP10: =IF(ISBLANK(M10),0,(N10-M10)*24) -> 0 | BQ10: =IF(BP10>$AY$1,1,IF(BP10>=$AX$1,0.5,0)) -> 0 | BR10: =BP10-BQ10-BS10-BT10 -> 0 | BS10: =IF(AND(N10>$AV$1, M10<$AW$1),(MIN(N10,$AW$1)-MAX(M10,$AV$1))*24,0) -> 0 | BT10: =IF(N10>$AW$1,(N10-MAX(M10,$AW$1))*24,0) -> 0 | BU10: =IF(ISBLANK(P10),0,(Q10-P10)*24) -> 0 | BV10: =IF(BU10>$AY$1,1,IF(BU10>=$AX$1,0.5,0)) -> 0 | BW10: =BU10-BV10-BX10-BY10 -> 0 | BX10: =IF(AND(Q10>$AV$1, P10<$AW$1),(MIN(Q10,$AW$1)-MAX(P10,$AV$1))*24,0) -> 0 | BY10: =IF(Q10>$AW$1,(Q10-MAX(P10,$AW$1))*24,0) -> 0 | BZ10: =IF(ISBLANK(S10),0,(T10-S10)*24) -> 0 | CA10: =IF(BZ10>$AY$1,1,IF(BZ10>=$AX$1,0.5,0)) -> 0 | CB10: =BZ10-CA10-CC10-CD10 -> 0 | CC10: =IF(AND(T10>$AV$1, S10<$AW$1),(MIN(T10,$AW$1)-MAX(S10,$AV$1))*24,0) -> 0 | CD10: =IF(T10>$AW$1,(T10-MAX(S10,$AW$1))*24,0) -> 0 | CE10: =IF(ISBLANK(V10),0,(W10-V10)*24) -> 0 | CF10: =IF(CE10>$AY$1,1,IF(CE10>=$AX$1,0.5,0)) -> 0 | CG10: =CE10-CF10-CH10-CI10 -> 0 | CH10: =IF(AND(W10>$AV$1, V10<$AW$1),(MIN(W10,$AW$1)-MAX(V10,$AV$1))*24,0) -> 0 | CI10: =IF(W10>$AW$1,(W10-MAX(V10,$AW$1))*24,0) -> 0 | CK10: =SUM(IF(F10>0,1,0),IF(I10>0,1,0),IF(L10>0,1,0),IF(O10>0,1,0),IF(R10>0,1,0),IF(U10>0,1,0),IF(X10>0,1,0)) -> 0
A11: =IF(ISNA(AZ11),"",AZ11) | F11: =BA11-BB11 -> 0 | I11: =BF11-BG11 -> 0 | L11: =BK11-BL11 -> 0 | O11: =BP11-BQ11 -> 0 | R11: =BU11-BV11 -> 0 | U11: =BZ11-CA11 -> 0 | X11: =CE11-CF11 -> 0 | AB11: =SUM(F11,I11,L11,O11,R11,U11,X11) -> 0 | AE11: =SUMIF($BC$1:$CI$1,AE$1,$BC11:$CI11)+AD11 -> 0 | AG11: =SUMIF($BC$1:$CI$1,AG$1,$BC11:$CI11)+AF11 -> 0 | AI11: =SUMIF($BC$1:$CI$1,AI$1,$BC11:$CI11)+AH11 -> 0 | AK11: =SUMIF($BC$1:$CI$1,AK$1,$BC11:$CI11)+AJ11 -> 0 | AM11: =SUMIF($BC$1:$CI$1,AM$1,$BC11:$CI11)+AL11 -> 0 | AO11: =SUMIF($BC$1:$CI$1,AO$1,$BC11:$CI11)+AN11 -> 0 | AP11: =CK11 -> 0 | AT11: =AE11+AG11+AI11+AK11+AM11+AO11+SUM(AQ11:AS11) -> 0 | AZ11: =VLOOKUP(C11,Employees!D:I,5,FALSE) -> #N/A | BA11: =IF(ISBLANK(D11),0,(E11-D11)*24) -> 0 | BB11: =IF(BA11>$AY$1,1,IF(BA11>=$AX$1,0.5,0)) -> 0 | BC11: =BA11-BB11-BD11-BE11 -> 0 | BD11: =IF(AND(E11>$AV$1, D11<$AW$1),(MIN(E11,$AW$1)-MAX(D11,$AV$1))*24,0) -> 0 | BE11: =IF(E11>$AW$1,(E11-MAX(D11,$AW$1))*24,0) -> 0 | BF11: =IF(ISBLANK(G11),0,(H11-G11)*24) -> 0 | BG11: =IF(BF11>$AY$1,1,IF(BF11>=$AX$1,0.5,0)) -> 0 | BH11: =BF11-BG11-BI11-BJ11 -> 0 | BI11: =IF(AND(H11>$AV$1,G11<$AW$1),(MIN(H11,$AW$1)-MAX(G11,$AV$1))*24,0) -> 0 | BJ11: =IF(H11>$AW$1,(H11-MAX(G11,$AW$1))*24,0) -> 0 | BK11: =IF(ISBLANK(J11),0,(K11-J11)*24) -> 0 | BL11: =IF(BK11>$AY$1,1,IF(BK11>=$AX$1,0.5,0)) -> 0 | BM11: =BK11-BL11-BN11-BO11 -> 0 | BN11: =IF(AND(K11>$AV$1, J11<$AW$1),(MIN(K11,$AW$1)-MAX(J11,$AV$1))*24,0) -> 0 | BO11: =IF(K11>$AW$1,(K11-MAX(J11,$AW$1))*24,0) -> 0 | BP11: =IF(ISBLANK(M11),0,(N11-M11)*24) -> 0 | BQ11: =IF(BP11>$AY$1,1,IF(BP11>=$AX$1,0.5,0)) -> 0 | BR11: =BP11-BQ11-BS11-BT11 -> 0 | BS11: =IF(AND(N11>$AV$1, M11<$AW$1),(MIN(N11,$AW$1)-MAX(M11,$AV$1))*24,0) -> 0 | BT11: =IF(N11>$AW$1,(N11-MAX(M11,$AW$1))*24,0) -> 0 | BU11: =IF(ISBLANK(P11),0,(Q11-P11)*24) -> 0 | BV11: =IF(BU11>$AY$1,1,IF(BU11>=$AX$1,0.5,0)) -> 0 | BW11: =BU11-BV11-BX11-BY11 -> 0 | BX11: =IF(AND(Q11>$AV$1, P11<$AW$1),(MIN(Q11,$AW$1)-MAX(P11,$AV$1))*24,0) -> 0 | BY11: =IF(Q11>$AW$1,(Q11-MAX(P11,$AW$1))*24,0) -> 0 | BZ11: =IF(ISBLANK(S11),0,(T11-S11)*24) -> 0 | CA11: =IF(BZ11>$AY$1,1,IF(BZ11>=$AX$1,0.5,0)) -> 0 | CB11: =BZ11-CA11-CC11-CD11 -> 0 | CC11: =IF(AND(T11>$AV$1, S11<$AW$1),(MIN(T11,$AW$1)-MAX(S11,$AV$1))*24,0) -> 0 | CD11: =IF(T11>$AW$1,(T11-MAX(S11,$AW$1))*24,0) -> 0 | CE11: =IF(ISBLANK(V11),0,(W11-V11)*24) -> 0 | CF11: =IF(CE11>$AY$1,1,IF(CE11>=$AX$1,0.5,0)) -> 0 | CG11: =CE11-CF11-CH11-CI11 -> 0 | CH11: =IF(AND(W11>$AV$1, V11<$AW$1),(MIN(W11,$AW$1)-MAX(V11,$AV$1))*24,0) -> 0 | CI11: =IF(W11>$AW$1,(W11-MAX(V11,$AW$1))*24,0) -> 0 | CK11: =SUM(IF(F11>0,1,0),IF(I11>0,1,0),IF(L11>0,1,0),IF(O11>0,1,0),IF(R11>0,1,0),IF(U11>0,1,0),IF(X11>0,1,0)) -> 0
A12: =IF(ISNA(AZ12),"",AZ12) | F12: =BA12-BB12 -> 0 | I12: =BF12-BG12 -> 0 | L12: =BK12-BL12 -> 0 | O12: =BP12-BQ12 -> 0 | R12: =BU12-BV12 -> 0 | U12: =BZ12-CA12 -> 0 | X12: =CE12-CF12 -> 0 | AB12: =SUM(F12,I12,L12,O12,R12,U12,X12) -> 0 | AE12: =SUMIF($BC$1:$CI$1,AE$1,$BC12:$CI12)+AD12 -> 0 | AG12: =SUMIF($BC$1:$CI$1,AG$1,$BC12:$CI12)+AF12 -> 0 | AI12: =SUMIF($BC$1:$CI$1,AI$1,$BC12:$CI12)+AH12 -> 0 | AK12: =SUMIF($BC$1:$CI$1,AK$1,$BC12:$CI12)+AJ12 -> 0 | AM12: =SUMIF($BC$1:$CI$1,AM$1,$BC12:$CI12)+AL12 -> 0 | AO12: =SUMIF($BC$1:$CI$1,AO$1,$BC12:$CI12)+AN12 -> 0 | AP12: =CK12 -> 0 | AT12: =AE12+AG12+AI12+AK12+AM12+AO12+SUM(AQ12:AS12) -> 0 | AZ12: =VLOOKUP(C12,Employees!D:I,5,FALSE) -> #N/A | BA12: =IF(ISBLANK(D12),0,(E12-D12)*24) -> 0 | BB12: =IF(BA12>$AY$1,1,IF(BA12>=$AX$1,0.5,0)) -> 0 | BC12: =BA12-BB12-BD12-BE12 -> 0 | BD12: =IF(AND(E12>$AV$1, D12<$AW$1),(MIN(E12,$AW$1)-MAX(D12,$AV$1))*24,0) -> 0 | BE12: =IF(E12>$AW$1,(E12-MAX(D12,$AW$1))*24,0) -> 0 | BF12: =IF(ISBLANK(G12),0,(H12-G12)*24) -> 0 | BG12: =IF(BF12>$AY$1,1,IF(BF12>=$AX$1,0.5,0)) -> 0 | BH12: =BF12-BG12-BI12-BJ12 -> 0 | BI12: =IF(AND(H12>$AV$1,G12<$AW$1),(MIN(H12,$AW$1)-MAX(G12,$AV$1))*24,0) -> 0 | BJ12: =IF(H12>$AW$1,(H12-MAX(G12,$AW$1))*24,0) -> 0 | BK12: =IF(ISBLANK(J12),0,(K12-J12)*24) -> 0 | BL12: =IF(BK12>$AY$1,1,IF(BK12>=$AX$1,0.5,0)) -> 0 | BM12: =BK12-BL12-BN12-BO12 -> 0 | BN12: =IF(AND(K12>$AV$1, J12<$AW$1),(MIN(K12,$AW$1)-MAX(J12,$AV$1))*24,0) -> 0 | BO12: =IF(K12>$AW$1,(K12-MAX(J12,$AW$1))*24,0) -> 0 | BP12: =IF(ISBLANK(M12),0,(N12-M12)*24) -> 0 | BQ12: =IF(BP12>$AY$1,1,IF(BP12>=$AX$1,0.5,0)) -> 0 | BR12: =BP12-BQ12-BS12-BT12 -> 0 | BS12: =IF(AND(N12>$AV$1, M12<$AW$1),(MIN(N12,$AW$1)-MAX(M12,$AV$1))*24,0) -> 0 | BT12: =IF(N12>$AW$1,(N12-MAX(M12,$AW$1))*24,0) -> 0 | BU12: =IF(ISBLANK(P12),0,(Q12-P12)*24) -> 0 | BV12: =IF(BU12>$AY$1,1,IF(BU12>=$AX$1,0.5,0)) -> 0 | BW12: =BU12-BV12-BX12-BY12 -> 0 | BX12: =IF(AND(Q12>$AV$1, P12<$AW$1),(MIN(Q12,$AW$1)-MAX(P12,$AV$1))*24,0) -> 0 | BY12: =IF(Q12>$AW$1,(Q12-MAX(P12,$AW$1))*24,0) -> 0 | BZ12: =IF(ISBLANK(S12),0,(T12-S12)*24) -> 0 | CA12: =IF(BZ12>$AY$1,1,IF(BZ12>=$AX$1,0.5,0)) -> 0 | CB12: =BZ12-CA12-CC12-CD12 -> 0 | CC12: =IF(AND(T12>$AV$1, S12<$AW$1),(MIN(T12,$AW$1)-MAX(S12,$AV$1))*24,0) -> 0 | CD12: =IF(T12>$AW$1,(T12-MAX(S12,$AW$1))*24,0) -> 0 | CE12: =IF(ISBLANK(V12),0,(W12-V12)*24) -> 0 | CF12: =IF(CE12>$AY$1,1,IF(CE12>=$AX$1,0.5,0)) -> 0 | CG12: =CE12-CF12-CH12-CI12 -> 0 | CH12: =IF(AND(W12>$AV$1, V12<$AW$1),(MIN(W12,$AW$1)-MAX(V12,$AV$1))*24,0) -> 0 | CI12: =IF(W12>$AW$1,(W12-MAX(V12,$AW$1))*24,0) -> 0 | CK12: =SUM(IF(F12>0,1,0),IF(I12>0,1,0),IF(L12>0,1,0),IF(O12>0,1,0),IF(R12>0,1,0),IF(U12>0,1,0),IF(X12>0,1,0)) -> 0
A13: =IF(ISNA(AZ13),"",AZ13) | F13: =BA13-BB13 -> 0 | I13: =BF13-BG13 -> 0 | L13: =BK13-BL13 -> 0 | O13: =BP13-BQ13 -> 0 | R13: =BU13-BV13 -> 0 | U13: =BZ13-CA13 -> 0 | X13: =CE13-CF13 -> 0 | AB13: =SUM(F13,I13,L13,O13,R13,U13,X13) -> 0 | AE13: =SUMIF($BC$1:$CI$1,AE$1,$BC13:$CI13)+AD13 -> 0 | AG13: =SUMIF($BC$1:$CI$1,AG$1,$BC13:$CI13)+AF13 -> 0 | AI13: =SUMIF($BC$1:$CI$1,AI$1,$BC13:$CI13)+AH13 -> 0 | AK13: =SUMIF($BC$1:$CI$1,AK$1,$BC13:$CI13)+AJ13 -> 0 | AM13: =SUMIF($BC$1:$CI$1,AM$1,$BC13:$CI13)+AL13 -> 0 | AO13: =SUMIF($BC$1:$CI$1,AO$1,$BC13:$CI13)+AN13 -> 0 | AP13: =CK13 -> 0 | AT13: =AE13+AG13+AI13+AK13+AM13+AO13+SUM(AQ13:AS13) -> 0 | AZ13: =VLOOKUP(C13,Employees!D:I,5,FALSE) -> #N/A | BA13: =IF(ISBLANK(D13),0,(E13-D13)*24) -> 0 | BB13: =IF(BA13>$AY$1,1,IF(BA13>=$AX$1,0.5,0)) -> 0 | BC13: =BA13-BB13-BD13-BE13 -> 0 | BD13: =IF(AND(E13>$AV$1, D13<$AW$1),(MIN(E13,$AW$1)-MAX(D13,$AV$1))*24,0) -> 0 | BE13: =IF(E13>$AW$1,(E13-MAX(D13,$AW$1))*24,0) -> 0 | BF13: =IF(ISBLANK(G13),0,(H13-G13)*24) -> 0 | BG13: =IF(BF13>$AY$1,1,IF(BF13>=$AX$1,0.5,0)) -> 0 | BH13: =BF13-BG13-BI13-BJ13 -> 0 | BI13: =IF(AND(H13>$AV$1,G13<$AW$1),(MIN(H13,$AW$1)-MAX(G13,$AV$1))*24,0) -> 0 | BJ13: =IF(H13>$AW$1,(H13-MAX(G13,$AW$1))*24,0) -> 0 | BK13: =IF(ISBLANK(J13),0,(K13-J13)*24) -> 0 | BL13: =IF(BK13>$AY$1,1,IF(BK13>=$AX$1,0.5,0)) -> 0 | BM13: =BK13-BL13-BN13-BO13 -> 0 | BN13: =IF(AND(K13>$AV$1, J13<$AW$1),(MIN(K13,$AW$1)-MAX(J13,$AV$1))*24,0) -> 0 | BO13: =IF(K13>$AW$1,(K13-MAX(J13,$AW$1))*24,0) -> 0 | BP13: =IF(ISBLANK(M13),0,(N13-M13)*24) -> 0 | BQ13: =IF(BP13>$AY$1,1,IF(BP13>=$AX$1,0.5,0)) -> 0 | BR13: =BP13-BQ13-BS13-BT13 -> 0 | BS13: =IF(AND(N13>$AV$1, M13<$AW$1),(MIN(N13,$AW$1)-MAX(M13,$AV$1))*24,0) -> 0 | BT13: =IF(N13>$AW$1,(N13-MAX(M13,$AW$1))*24,0) -> 0 | BU13: =IF(ISBLANK(P13),0,(Q13-P13)*24) -> 0 | BV13: =IF(BU13>$AY$1,1,IF(BU13>=$AX$1,0.5,0)) -> 0 | BW13: =BU13-BV13-BX13-BY13 -> 0 | BX13: =IF(AND(Q13>$AV$1, P13<$AW$1),(MIN(Q13,$AW$1)-MAX(P13,$AV$1))*24,0) -> 0 | BY13: =IF(Q13>$AW$1,(Q13-MAX(P13,$AW$1))*24,0) -> 0 | BZ13: =IF(ISBLANK(S13),0,(T13-S13)*24) -> 0 | CA13: =IF(BZ13>$AY$1,1,IF(BZ13>=$AX$1,0.5,0)) -> 0 | CB13: =BZ13-CA13-CC13-CD13 -> 0 | CC13: =IF(AND(T13>$AV$1, S13<$AW$1),(MIN(T13,$AW$1)-MAX(S13,$AV$1))*24,0) -> 0 | CD13: =IF(T13>$AW$1,(T13-MAX(S13,$AW$1))*24,0) -> 0 | CE13: =IF(ISBLANK(V13),0,(W13-V13)*24) -> 0 | CF13: =IF(CE13>$AY$1,1,IF(CE13>=$AX$1,0.5,0)) -> 0 | CG13: =CE13-CF13-CH13-CI13 -> 0 | CH13: =IF(AND(W13>$AV$1, V13<$AW$1),(MIN(W13,$AW$1)-MAX(V13,$AV$1))*24,0) -> 0 | CI13: =IF(W13>$AW$1,(W13-MAX(V13,$AW$1))*24,0) -> 0 | CK13: =SUM(IF(F13>0,1,0),IF(I13>0,1,0),IF(L13>0,1,0),IF(O13>0,1,0),IF(R13>0,1,0),IF(U13>0,1,0),IF(X13>0,1,0)) -> 0
A14: =IF(ISNA(AZ14),"",AZ14) | F14: =BA14-BB14 -> 0 | I14: =BF14-BG14 -> 0 | L14: =BK14-BL14 -> 0 | O14: =BP14-BQ14 -> 0 | R14: =BU14-BV14 -> 0 | U14: =BZ14-CA14 -> 0 | X14: =CE14-CF14 -> 0 | AB14: =SUM(F14,I14,L14,O14,R14,U14,X14) -> 0 | AE14: =SUMIF($BC$1:$CI$1,AE$1,$BC14:$CI14)+AD14 -> 0 | AG14: =SUMIF($BC$1:$CI$1,AG$1,$BC14:$CI14)+AF14 -> 0 | AI14: =SUMIF($BC$1:$CI$1,AI$1,$BC14:$CI14)+AH14 -> 0 | AK14: =SUMIF($BC$1:$CI$1,AK$1,$BC14:$CI14)+AJ14 -> 0 | AM14: =SUMIF($BC$1:$CI$1,AM$1,$BC14:$CI14)+AL14 -> 0 | AO14: =SUMIF($BC$1:$CI$1,AO$1,$BC14:$CI14)+AN14 -> 0 | AP14: =CK14 -> 0 | AT14: =AE14+AG14+AI14+AK14+AM14+AO14+SUM(AQ14:AS14) -> 0 | AZ14: =VLOOKUP(C14,Employees!D:I,5,FALSE) -> #N/A | BA14: =IF(ISBLANK(D14),0,(E14-D14)*24) -> 0 | BB14: =IF(BA14>$AY$1,1,IF(BA14>=$AX$1,0.5,0)) -> 0 | BC14: =BA14-BB14-BD14-BE14 -> 0 | BD14: =IF(AND(E14>$AV$1, D14<$AW$1),(MIN(E14,$AW$1)-MAX(D14,$AV$1))*24,0) -> 0 | BE14: =IF(E14>$AW$1,(E14-MAX(D14,$AW$1))*24,0) -> 0 | BF14: =IF(ISBLANK(G14),0,(H14-G14)*24) -> 0 | BG14: =IF(BF14>$AY$1,1,IF(BF14>=$AX$1,0.5,0)) -> 0 | BH14: =BF14-BG14-BI14-BJ14 -> 0 | BI14: =IF(AND(H14>$AV$1,G14<$AW$1),(MIN(H14,$AW$1)-MAX(G14,$AV$1))*24,0) -> 0 | BJ14: =IF(H14>$AW$1,(H14-MAX(G14,$AW$1))*24,0) -> 0 | BK14: =IF(ISBLANK(J14),0,(K14-J14)*24) -> 0 | BL14: =IF(BK14>$AY$1,1,IF(BK14>=$AX$1,0.5,0)) -> 0 | BM14: =BK14-BL14-BN14-BO14 -> 0 | BN14: =IF(AND(K14>$AV$1, J14<$AW$1),(MIN(K14,$AW$1)-MAX(J14,$AV$1))*24,0) -> 0 | BO14: =IF(K14>$AW$1,(K14-MAX(J14,$AW$1))*24,0) -> 0 | BP14: =IF(ISBLANK(M14),0,(N14-M14)*24) -> 0 | BQ14: =IF(BP14>$AY$1,1,IF(BP14>=$AX$1,0.5,0)) -> 0 | BR14: =BP14-BQ14-BS14-BT14 -> 0 | BS14: =IF(AND(N14>$AV$1, M14<$AW$1),(MIN(N14,$AW$1)-MAX(M14,$AV$1))*24,0) -> 0 | BT14: =IF(N14>$AW$1,(N14-MAX(M14,$AW$1))*24,0) -> 0 | BU14: =IF(ISBLANK(P14),0,(Q14-P14)*24) -> 0 | BV14: =IF(BU14>$AY$1,1,IF(BU14>=$AX$1,0.5,0)) -> 0 | BW14: =BU14-BV14-BX14-BY14 -> 0 | BX14: =IF(AND(Q14>$AV$1, P14<$AW$1),(MIN(Q14,$AW$1)-MAX(P14,$AV$1))*24,0) -> 0 | BY14: =IF(Q14>$AW$1,(Q14-MAX(P14,$AW$1))*24,0) -> 0 | BZ14: =IF(ISBLANK(S14),0,(T14-S14)*24) -> 0 | CA14: =IF(BZ14>$AY$1,1,IF(BZ14>=$AX$1,0.5,0)) -> 0 | CB14: =BZ14-CA14-CC14-CD14 -> 0 | CC14: =IF(AND(T14>$AV$1, S14<$AW$1),(MIN(T14,$AW$1)-MAX(S14,$AV$1))*24,0) -> 0 | CD14: =IF(T14>$AW$1,(T14-MAX(S14,$AW$1))*24,0) -> 0 | CE14: =IF(ISBLANK(V14),0,(W14-V14)*24) -> 0 | CF14: =IF(CE14>$AY$1,1,IF(CE14>=$AX$1,0.5,0)) -> 0 | CG14: =CE14-CF14-CH14-CI14 -> 0 | CH14: =IF(AND(W14>$AV$1, V14<$AW$1),(MIN(W14,$AW$1)-MAX(V14,$AV$1))*24,0) -> 0 | CI14: =IF(W14>$AW$1,(W14-MAX(V14,$AW$1))*24,0) -> 0 | CK14: =SUM(IF(F14>0,1,0),IF(I14>0,1,0),IF(L14>0,1,0),IF(O14>0,1,0),IF(R14>0,1,0),IF(U14>0,1,0),IF(X14>0,1,0)) -> 0
... A100: =IF(ISNA(AZ100),"",AZ100) | F100: =BA100-BB100 -> 0 | I100: =BF100-BG100 -> 0 | L100: =BK100-BL100 -> 0 | O100: =BP100-BQ100 -> 0 | R100: =BU100-BV100 -> 0 | U100: =BZ100-CA100 -> 0 | X100: =CE100-CF100 -> 0 | AB100: =SUM(F100,I100,L100,O100,R100,U100,X100) -> 0 | AE100: =SUMIF($BC$1:$CI$1,AE$1,$BC100:$CI100)+AD100 -> 0 | AG100: =SUMIF($BC$1:$CI$1,AG$1,$BC100:$CI100)+AF100 -> 0 | AI100: =SUMIF($BC$1:$CI$1,AI$1,$BC100:$CI100)+AH100 -> 0 | AK100: =SUMIF($BC$1:$CI$1,AK$1,$BC100:$CI100)+AJ100 -> 0 | AM100: =SUMIF($BC$1:$CI$1,AM$1,$BC100:$CI100)+AL100 -> 0 | AO100: =SUMIF($BC$1:$CI$1,AO$1,$BC100:$CI100)+AN100 -> 0 | AP100: =CK100 -> 0 | AT100: =AE100+AG100+AI100+AK100+AM100+AO100+SUM(AQ100:AS100) -> 0 | AZ100: =VLOOKUP(C100,Employees!D:I,5,FALSE) -> #N/A | BA100: =IF(ISBLANK(D100),0,(E100-D100)*24) -> 0 | BB100: =IF(BA100>$AY$1,1,IF(BA100>=$AX$1,0.5,0)) -> 0 | BC100: =BA100-BB100-BD100-BE100 -> 0 | BD100: =IF(AND(E100>$AV$1, D100<$AW$1),(MIN(E100,$AW$1)-MAX(D100,$AV$1))*24,0) -> 0 | BE100: =IF(E100>$AW$1,(E100-MAX(D100,$AW$1))*24,0) -> 0 | BF100: =IF(ISBLANK(G100),0,(H100-G100)*24) -> 0 | BG100: =IF(BF100>$AY$1,1,IF(BF100>=$AX$1,0.5,0)) -> 0 | BH100: =BF100-BG100-BI100-BJ100 -> 0 | BI100: =IF(AND(H100>$AV$1,G100<$AW$1),(MIN(H100,$AW$1)-MAX(G100,$AV$1))*24,0) -> 0 | BJ100: =IF(H100>$AW$1,(H100-MAX(G100,$AW$1))*24,0) -> 0 | BK100: =IF(ISBLANK(J100),0,(K100-J100)*24) -> 0 | BL100: =IF(BK100>$AY$1,1,IF(BK100>=$AX$1,0.5,0)) -> 0 | BM100: =BK100-BL100-BN100-BO100 -> 0 | BN100: =IF(AND(K100>$AV$1, J100<$AW$1),(MIN(K100,$AW$1)-MAX(J100,$AV$1))*24,0) -> 0 | BO100: =IF(K100>$AW$1,(K100-MAX(J100,$AW$1))*24,0) -> 0 | BP100: =IF(ISBLANK(M100),0,(N100-M100)*24) -> 0 | BQ100: =IF(BP100>$AY$1,1,IF(BP100>=$AX$1,0.5,0)) -> 0 | BR100: =BP100-BQ100-BS100-BT100 -> 0 | BS100: =IF(AND(N100>$AV$1, M100<$AW$1),(MIN(N100,$AW$1)-MAX(M100,$AV$1))*24,0) -> 0 | BT100: =IF(N100>$AW$1,(N100-MAX(M100,$AW$1))*24,0) -> 0 | BU100: =IF(ISBLANK(P100),0,(Q100-P100)*24) -> 0 | BV100: =IF(BU100>$AY$1,1,IF(BU100>=$AX$1,0.5,0)) -> 0 | BW100: =BU100-BV100-BX100-BY100 -> 0 | BX100: =IF(AND(Q100>$AV$1, P100<$AW$1),(MIN(Q100,$AW$1)-MAX(P100,$AV$1))*24,0) -> 0 | BY100: =IF(Q100>$AW$1,(Q100-MAX(P100,$AW$1))*24,0) -> 0 | BZ100: =IF(ISBLANK(S100),0,(T100-S100)*24) -> 0 | CA100: =IF(BZ100>$AY$1,1,IF(BZ100>=$AX$1,0.5,0)) -> 0 | CB100: =BZ100-CA100-CC100-CD100 -> 0 | CC100: =IF(AND(T100>$AV$1, S100<$AW$1),(MIN(T100,$AW$1)-MAX(S100,$AV$1))*24,0) -> 0 | CD100: =IF(T100>$AW$1,(T100-MAX(S100,$AW$1))*24,0) -> 0 | CE100: =IF(ISBLANK(V100),0,(W100-V100)*24) -> 0 | CF100: =IF(CE100>$AY$1,1,IF(CE100>=$AX$1,0.5,0)) -> 0 | CG100: =CE100-CF100-CH100-CI100 -> 0 | CH100: =IF(AND(W100>$AV$1, V100<$AW$1),(MIN(W100,$AW$1)-MAX(V100,$AV$1))*24,0) -> 0 | CI100: =IF(W100>$AW$1,(W100-MAX(V100,$AW$1))*24,0) -> 0 | CK100: =SUM(IF(F100>0,1,0),IF(I100>0,1,0),IF(L100>0,1,0),IF(O100>0,1,0),IF(R100>0,1,0),IF(U100>0,1,0),IF(X100>0,1,0)) -> 0

Sheet Week 2 Roster
A1: Employee ID | B1: Store | C1: Preferred Name | D1: ='Week 1 Roster'!V1+1 -> 45838 | E1: =TEXT(D1,"dddd") -> Monday | F1: =IF(ISNUMBER(MATCH(D1,'Public Holidays'!$A:$A,0)),"Pub",IF(WEEKDAY(D1,2)=7,"Sun",IF(WEEKDAY(D1,2)=6,"Sat","Ord"))) -> Ord | G1: =D1+1 -> 45839 | H1: =TEXT(G1,"dddd") -> Tuesday | I1: =IF(ISNUMBER(MATCH(G1,'Public Holidays'!$A:$A,0)),"Pub",IF(WEEKDAY(G1,2)=7,"Sun",IF(WEEKDAY(G1,2)=6,"Sat","Ord"))) -> Ord | J1: =G1+1 -> 45840 | K1: =TEXT(J1,"dddd") -> Wednesday | L1: =IF(ISNUMBER(MATCH(J1,'Public Holidays'!$A:$A,0)),"Pub",IF(WEEKDAY(J1,2)=7,"Sun",IF(WEEKDAY(J1,2)=6,"Sat","Ord"))) -> Ord | M1: =J1+1 -> 45841 | N1: =TEXT(M1,"dddd") -> Thursday | O1: =IF(ISNUMBER(MATCH(M1,'Public Holidays'!$A:$A,0)),"Pub",IF(WEEKDAY(M1,2)=7,"Sun",IF(WEEKDAY(M1,2)=6,"Sat","Ord"))) -> Ord | P1: =M1+1 -> 45842 | Q1: =TEXT(P1,"dddd") -> Friday | R1: =IF(ISNUMBER(MATCH(P1,'Public Holidays'!$A:$A,0)),"Pub",IF(WEEKDAY(P1,2)=7,"Sun",IF(WEEKDAY(P1,2)=6,"Sat","Ord"))) -> Ord | S1: =P1+1 -> 45843 | T1: =TEXT(S1,"dddd") -> Saturday | U1: =IF(ISNUMBER(MATCH(S1,'Public Holidays'!$A:$A,0)),"Pub",IF(WEEKDAY(S1,2)=7,"Sun",IF(WEEKDAY(S1,2)=6,"Sat","Ord"))) -> Sat | V1: =S1+1 -> 45844 | W1: =TEXT(V1,"dddd") -> Sunday | X1: =IF(ISNUMBER(MATCH(V1,'Public Holidays'!$A:$A,0)),"Pub",IF(WEEKDAY(V1,2)=7,"Sun",IF(WEEKDAY(V1,2)=6,"Sat","Ord"))) -> Sun | Y1: =V1+1 -> 45845 | Z1: =TEXT(Y1,"dddd") -> Monday | AA1: =IF(ISNUMBER(MATCH(Y1,'Public Holidays'!$A:$A,0)),"Pub",IF(WEEKDAY(Y1,2)=7,"Sun",IF(WEEKDAY(Y1,2)=6,"Sat","Ord"))) -> Ord | AB1: Rostered Total | AD1: Add | AE1: Ord | AF1: Add | AG1: Sat | AH1: Add | AI1: Sun | AJ1: Add | AK1: Pub | AL1: Add | AM1: Eve 1 | AN1: Add | AO1: Eve 2 | AP1: No. of Shifts | AQ1: Personal Leave | AR1: Annual Leave | AS1: Unpaid Leave | AT1: Adjusted Total | AU1: Comment | AV1: 0.91666667 | AW1: 1 | AX1: 5.5 | AY1: 9 | AZ1: Employee ID | BA1: Dr1 | BB1: Br1 | BC1: =F1 -> Ord | BD1: =IF(BC1="Ord","Eve 1", BC1) -> Eve 1 | BE1: =IF(BH1="Ord","Eve 2",BH1) -> Eve 2 | BF1: Dr2 | BG1: Br2 | BH1: =I1 -> Ord | BI1: =IF(BH1="Ord","Eve 1", BH1) -> Eve 1 | BJ1: =IF(BM1="Ord","Eve 2",BM1) -> Eve 2 | BK1: Dr3 | BL1: Br3 | BM1: =L1 -> Ord | BN1: =IF(BM1="Ord","Eve 1", BM1) -> Eve 1 | BO1: =IF(BR1="Ord","Eve 2",BR1) -> Eve 2 | BP1: Dr4 | BQ1: Br4 | BR1: =O1 -> Ord | BS1: =IF(BR1="Ord","Eve 1", BR1) -> Eve 1 | BT1: =IF(BW1="Ord","Eve 2",BW1) -> Eve 2 | BU1: Dr5 | BV1: Br5 | BW1: =R1 -> Ord | BX1: =IF(BW1="Ord","Eve 1", BW1) -> Eve 1 | BY1: =IF(CB1="Ord","Eve 2",CB1) -> Sat | BZ1: Dr6 | CA1: Br6 | CB1: =U1 -> Sat | CC1: =IF(CB1="Ord","Eve 1", CB1) -> Sat | CD1: =IF(CG1="Ord","Eve 2",CG1) -> Sun | CE1: Dr7 | CF1: Br7 | CG1: =X1 -> Sun | CH1: =IF(CG1="Ord","Eve 1", CG1) -> Sun | CI1: =IF(CJ1="Ord","Eve 2",CJ1) -> Eve 2 | CJ1: =AA1 -> Ord | CK1: No. of Shifts
A2: =IF(ISNA(AZ2),"",AZ2) -> 10004 | B2: 501 | C2: Dan Yi | F2: =BA2-BB2 -> 0 | I2: =BF2-BG2 -> 0 | L2: =BK2-BL2 -> 0 | O2: =BP2-BQ2 -> 0 | R2: =BU2-BV2 -> 0 | U2: =BZ2-CA2 -> 0 | X2: =CE2-CF2 -> 0 | AB2: =SUM(F2,I2,L2,O2,R2,U2,X2) -> 0 | AE2: =SUMIF($BC$1:$CI$1,AE$1,$BC2:$CI2)+AD2 -> 0 | AG2: =SUMIF($BC$1:$CI$1,AG$1,$BC2:$CI2)+AF2 -> 0 | AI2: =SUMIF($BC$1:$CI$1,AI$1,$BC2:$CI2)+AH2 -> 0 | AK2: =SUMIF($BC$1:$CI$1,AK$1,$BC2:$CI2)+AJ2 -> 0 | AM2: =SUMIF($BC$1:$CI$1,AM$1,$BC2:$CI2)+AL2 -> 0 | AO2: =SUMIF($BC$1:$CI$1,AO$1,$BC2:$CI2)+AN2 -> 0 | AP2: =CK2 -> 0 | AT2: =AE2+AG2+AI2+AK2+AM2+AO2+SUM(AQ2:AS2) -> 0 | AZ2: =VLOOKUP(C2,Employees!D:I,6,FALSE) -> 10004 | BA2: =IF(ISBLANK(D2),0,(E2-D2)*24) -> 0 | BB2: =IF(BA2>$AY$1,1,IF(BA2>=$AX$1,0.5,0)) -> 0 | BC2: =BA2-BB2-BD2-BE2 -> 0 | BD2: =IF(AND(E2>$AV$1, D2<$AW$1),(MIN(E2,$AW$1)-MAX(D2,$AV$1))*24,0) -> 0 | BE2: =IF(E2>$AW$1,(E2-MAX(D2,$AW$1))*24,0) -> 0 | BF2: =IF(ISBLANK(G2),0,(H2-G2)*24) -> 0 | BG2: =IF(BF2>$AY$1,1,IF(BF2>=$AX$1,0.5,0)) -> 0 | BH2: =BF2-BG2-BI2-BJ2 -> 0 | BI2: =IF(AND(H2>$AV$1,G2<$AW$1),(MIN(H2,$AW$1)-MAX(G2,$AV$1))*24,0) -> 0 | BJ2: =IF(H2>$AW$1,(H2-MAX(G2,$AW$1))*24,0) -> 0 | BK2: =IF(ISBLANK(J2),0,(K2-J2)*24) -> 0 | BL2: =IF(BK2>$AY$1,1,IF(BK2>=$AX$1,0.5,0)) -> 0 | BM2: =BK2-BL2-BN2-BO2 -> 0 | BN2: =IF(AND(K2>$AV$1, J2<$AW$1),(MIN(K2,$AW$1)-MAX(J2,$AV$1))*24,0) -> 0 | BO2: =IF(K2>$AW$1,(K2-MAX(J2,$AW$1))*24,0) -> 0 | BP2: =IF(ISBLANK(M2),0,(N2-M2)*24) -> 0 | BQ2: =IF(BP2>$AY$1,1,IF(BP2>=$AX$1,0.5,0)) -> 0 | BR2: =BP2-BQ2-BS2-BT2 -> 0 | BS2: =IF(AND(N2>$AV$1, M2<$AW$1),(MIN(N2,$AW$1)-MAX(M2,$AV$1))*24,0) -> 0 | BT2: =IF(N2>$AW$1,(N2-MAX(M2,$AW$1))*24,0) -> 0 | BU2: =IF(ISBLANK(P2),0,(Q2-P2)*24) -> 0 | BV2: =IF(BU2>$AY$1,1,IF(BU2>=$AX$1,0.5,0)) -> 0 | BW2: =BU2-BV2-BX2-BY2 -> 0 | BX2: =IF(AND(Q2>$AV$1, P2<$AW$1),(MIN(Q2,$AW$1)-MAX(P2,$AV$1))*24,0) -> 0 | BY2: =IF(Q2>$AW$1,(Q2-MAX(P2,$AW$1))*24,0) -> 0 | BZ2: =IF(ISBLANK(S2),0,(T2-S2)*24) -> 0 | CA2: =IF(BZ2>$AY$1,1,IF(BZ2>=$AX$1,0.5,0)) -> 0 | CB2: =BZ2-CA2-CC2-CD2 -> 0 | CC2: =IF(AND(T2>$AV$1, S2<$AW$1),(MIN(T2,$AW$1)-MAX(S2,$AV$1))*24,0) -> 0 | CD2: =IF(T2>$AW$1,(T2-MAX(S2,$AW$1))*24,0) -> 0 | CE2: =IF(ISBLANK(V2),0,(W2-V2)*24) -> 0 | CF2: =IF(CE2>$AY$1,1,IF(CE2>=$AX$1,0.5,0)) -> 0 | CG2: =CE2-CF2-CH2-CI2 -> 0 | CH2: =IF(AND(W2>$AV$1, V2<$AW$1),(MIN(W2,$AW$1)-MAX(V2,$AV$1))*24,0) -> 0 | CI2: =IF(W2>$AW$1,(W2-MAX(V2,$AW$1))*24,0) -> 0 | CK2: =SUM(IF(F2>0,1,0),IF(I2>0,1,0),IF(L2>0,1,0),IF(O2>0,1,0),IF(R2>0,1,0),IF(U2>0,1,0),IF(X2>0,1,0)) -> 0
A3: =IF(ISNA(AZ3),"",AZ3) | F3: =BA3-BB3 -> 0 | I3: =BF3-BG3 -> 0 | L3: =BK3-BL3 -> 0 | O3: =BP3-BQ3 -> 0 | R3: =BU3-BV3 -> 0 | U3: =BZ3-CA3 -> 0 | X3: =CE3-CF3 -> 0 | AB3: =SUM(F3,I3,L3,O3,R3,U3,X3) -> 0 | AE3: =SUMIF($BC$1:$CI$1,AE$1,$BC3:$CI3)+AD3 -> 0 | AG3: =SUMIF($BC$1:$CI$1,AG$1,$BC3:$CI3)+AF3 -> 0 | AI3: =SUMIF($BC$1:$CI$1,AI$1,$BC3:$CI3)+AH3 -> 0 | AK3: =SUMIF($BC$1:$CI$1,AK$1,$BC3:$CI3)+AJ3 -> 0 | AM3: =SUMIF($BC$1:$CI$1,AM$1,$BC3:$CI3)+AL3 -> 0 | AO3: =SUMIF($BC$1:$CI$1,AO$1,$BC3:$CI3)+AN3 -> 0 | AP3: =CK3 -> 0 | AT3: =AE3+AG3+AI3+AK3+AM3+AO3+SUM(AQ3:AS3) -> 0 | AZ3: =VLOOKUP(C3,Employees!D:I,5,FALSE) -> #N/A | BA3: =IF(ISBLANK(D3),0,(E3-D3)*24) -> 0 | BB3: =IF(BA3>$AY$1,1,IF(BA3>=$AX$1,0.5,0)) -> 0 | BC3: =BA3-BB3-BD3-BE3 -> 0 | BD3: =IF(AND(E3>$AV$1, D3<$AW$1),(MIN(E3,$AW$1)-MAX(D3,$AV$1))*24,0) -> 0 | BE3: =IF(E3>$AW$1,(E3-MAX(D3,$AW$1))*24,0) -> 0 | BF3: =IF(ISBLANK(G3),0,(H3-G3)*24) -> 0 | BG3: =IF(BF3>$AY$1,1,IF(BF3>=$AX$1,0.5,0)) -> 0 | BH3: =BF3-BG3-BI3-BJ3 -> 0 | BI3: =IF(AND(H3>$AV$1,G3<$AW$1),(MIN(H3,$AW$1)-MAX(G3,$AV$1))*24,0) -> 0 | BJ3: =IF(H3>$AW$1,(H3-MAX(G3,$AW$1))*24,0) -> 0 | BK3: =IF(ISBLANK(J3),0,(K3-J3)*24) -> 0 | BL3: =IF(BK3>$AY$1,1,IF(BK3>=$AX$1,0.5,0)) -> 0 | BM3: =BK3-BL3-BN3-BO3 -> 0 | BN3: =IF(AND(K3>$AV$1, J3<$AW$1),(MIN(K3,$AW$1)-MAX(J3,$AV$1))*24,0) -> 0 | BO3: =IF(K3>$AW$1,(K3-MAX(J3,$AW$1))*24,0) -> 0 | BP3: =IF(ISBLANK(M3),0,(N3-M3)*24) -> 0 | BQ3: =IF(BP3>$AY$1,1,IF(BP3>=$AX$1,0.5,0)) -> 0 | BR3: =BP3-BQ3-BS3-BT3 -> 0 | BS3: =IF(AND(N3>$AV$1, M3<$AW$1),(MIN(N3,$AW$1)-MAX(M3,$AV$1))*24,0) -> 0 | BT3: =IF(N3>$AW$1,(N3-MAX(M3,$AW$1))*24,0) -> 0 | BU3: =IF(ISBLANK(P3),0,(Q3-P3)*24) -> 0 | BV3: =IF(BU3>$AY$1,1,IF(BU3>=$AX$1,0.5,0)) -> 0 | BW3: =BU3-BV3-BX3-BY3 -> 0 | BX3: =IF(AND(Q3>$AV$1, P3<$AW$1),(MIN(Q3,$AW$1)-MAX(P3,$AV$1))*24,0) -> 0 | BY3: =IF(Q3>$AW$1,(Q3-MAX(P3,$AW$1))*24,0) -> 0 | BZ3: =IF(ISBLANK(S3),0,(T3-S3)*24) -> 0 | CA3: =IF(BZ3>$AY$1,1,IF(BZ3>=$AX$1,0.5,0)) -> 0 | CB3: =BZ3-CA3-CC3-CD3 -> 0 | CC3: =IF(AND(T3>$AV$1, S3<$AW$1),(MIN(T3,$AW$1)-MAX(S3,$AV$1))*24,0) -> 0 | CD3: =IF(T3>$AW$1,(T3-MAX(S3,$AW$1))*24,0) -> 0 | CE3: =IF(ISBLANK(V3),0,(W3-V3)*24) -> 0 | CF3: =IF(CE3>$AY$1,1,IF(CE3>=$AX$1,0.5,0)) -> 0 | CG3: =CE3-CF3-CH3-CI3 -> 0 | CH3: =IF(AND(W3>$AV$1, V3<$AW$1),(MIN(W3,$AW$1)-MAX(V3,$AV$1))*24,0) -> 0 | CI3: =IF(W3>$AW$1,(W3-MAX(V3,$AW$1))*24,0) -> 0 | CK3: =SUM(IF(F3>0,1,0),IF(I3>0,1,0),IF(L3>0,1,0),IF(O3>0,1,0),IF(R3>0,1,0),IF(U3>0,1,0),IF(X3>0,1,0)) -> 0
A4: =IF(ISNA(AZ4),"",AZ4) | F4: =BA4-BB4 -> 0 | I4: =BF4-BG4 -> 0 | L4: =BK4-BL4 -> 0 | O4: =BP4-BQ4 -> 0 | R4: =BU4-BV4 -> 0 | U4: =BZ4-CA4 -> 0 | X4: =CE4-CF4 -> 0 | AB4: =SUM(F4,I4,L4,O4,R4,U4,X4) -> 0 | AE4: =SUMIF($BC$1:$CI$1,AE$1,$BC4:$CI4)+AD4 -> 0 | AG4: =SUMIF($BC$1:$CI$1,AG$1,$BC4:$CI4)+AF4 -> 0 | AI4: =SUMIF($BC$1:$CI$1,AI$1,$BC4:$CI4)+AH4 -> 0 | AK4: =SUMIF($BC$1:$CI$1,AK$1,$BC4:$CI4)+AJ4 -> 0 | AM4: =SUMIF($BC$1:$CI$1,AM$1,$BC4:$CI4)+AL4 -> 0 | AO4: =SUMIF($BC$1:$CI$1,AO$1,$BC4:$CI4)+AN4 -> 0 | AP4: =CK4 -> 0 | AT4: =AE4+AG4+AI4+AK4+AM4+AO4+SUM(AQ4:AS4) -> 0 | AZ4: =VLOOKUP(C4,Employees!D:I,5,FALSE) -> #N/A | BA4: =IF(ISBLANK(D4),0,(E4-D4)*24) -> 0 | BB4: =IF(BA4>$AY$1,1,IF(BA4>=$AX$1,0.5,0)) -> 0 | BC4: =BA4-BB4-BD4-BE4 -> 0 | BD4: =IF(AND(E4>$AV$1, D4<$AW$1),(MIN(E4,$AW$1)-MAX(D4,$AV$1))*24,0) -> 0 | BE4: =IF(E4>$AW$1,(E4-MAX(D4,$AW$1))*24,0) -> 0 | BF4: =IF(ISBLANK(G4),0,(H4-G4)*24) -> 0 | BG4: =IF(BF4>$AY$1,1,IF(BF4>=$AX$1,0.5,0)) -> 0 | BH4: =BF4-BG4-BI4-BJ4 -> 0 | BI4: =IF(AND(H4>$AV$1,G4<$AW$1),(MIN(H4,$AW$1)-MAX(G4,$AV$1))*24,0) -> 0 | BJ4: =IF(H4>$AW$1,(H4-MAX(G4,$AW$1))*24,0) -> 0 | BK4: =IF(ISBLANK(J4),0,(K4-J4)*24) -> 0 | BL4: =IF(BK4>$AY$1,1,IF(BK4>=$AX$1,0.5,0)) -> 0 | BM4: =BK4-BL4-BN4-BO4 -> 0 | BN4: =IF(AND(K4>$AV$1, J4<$AW$1),(MIN(K4,$AW$1)-MAX(J4,$AV$1))*24,0) -> 0 | BO4: =IF(K4>$AW$1,(K4-MAX(J4,$AW$1))*24,0) -> 0 | BP4: =IF(ISBLANK(M4),0,(N4-M4)*24) -> 0 | BQ4: =IF(BP4>$AY$1,1,IF(BP4>=$AX$1,0.5,0)) -> 0 | BR4: =BP4-BQ4-BS4-BT4 -> 0 | BS4: =IF(AND(N4>$AV$1, M4<$AW$1),(MIN(N4,$AW$1)-MAX(M4,$AV$1))*24,0) -> 0 | BT4: =IF(N4>$AW$1,(N4-MAX(M4,$AW$1))*24,0) -> 0 | BU4: =IF(ISBLANK(P4),0,(Q4-P4)*24) -> 0 | BV4: =IF(BU4>$AY$1,1,IF(BU4>=$AX$1,0.5,0)) -> 0 | BW4: =BU4-BV4-BX4-BY4 -> 0 | BX4: =IF(AND(Q4>$AV$1, P4<$AW$1),(MIN(Q4,$AW$1)-MAX(P4,$AV$1))*24,0) -> 0 | BY4: =IF(Q4>$AW$1,(Q4-MAX(P4,$AW$1))*24,0) -> 0 | BZ4: =IF(ISBLANK(S4),0,(T4-S4)*24) -> 0 | CA4: =IF(BZ4>$AY$1,1,IF(BZ4>=$AX$1,0.5,0)) -> 0 | CB4: =BZ4-CA4-CC4-CD4 -> 0 | CC4: =IF(AND(T4>$AV$1, S4<$AW$1),(MIN(T4,$AW$1)-MAX(S4,$AV$1))*24,0) -> 0 | CD4: =IF(T4>$AW$1,(T4-MAX(S4,$AW$1))*24,0) -> 0 | CE4: =IF(ISBLANK(V4),0,(W4-V4)*24) -> 0 | CF4: =IF(CE4>$AY$1,1,IF(CE4>=$AX$1,0.5,0)) -> 0 | CG4: =CE4-CF4-CH4-CI4 -> 0 | CH4: =IF(AND(W4>$AV$1, V4<$AW$1),(MIN(W4,$AW$1)-MAX(V4,$AV$1))*24,0) -> 0 | CI4: =IF(W4>$AW$1,(W4-MAX(V4,$AW$1))*24,0) -> 0 | CK4: =SUM(IF(F4>0,1,0),IF(I4>0,1,0),IF(L4>0,1,0),IF(O4>0,1,0),IF(R4>0,1,0),IF(U4>0,1,0),IF(X4>0,1,0)) -> 0
A5: =IF(ISNA(AZ5),"",AZ5) | F5: =BA5-BB5 -> 0 | I5: =BF5-BG5 -> 0 | L5: =BK5-BL5 -> 0 | O5: =BP5-BQ5 -> 0 | R5: =BU5-BV5 -> 0 | U5: =BZ5-CA5 -> 0 | X5: =CE5-CF5 -> 0 | AB5: =SUM(F5,I5,L5,O5,R5,U5,X5) -> 0 | AE5: =SUMIF($BC$1:$CI$1,AE$1,$BC5:$CI5)+AD5 -> 0 | AG5: =SUMIF($BC$1:$CI$1,AG$1,$BC5:$CI5)+AF5 -> 0 | AI5: =SUMIF($BC$1:$CI$1,AI$1,$BC5:$CI5)+AH5 -> 0 | AK5: =SUMIF($BC$1:$CI$1,AK$1,$BC5:$CI5)+AJ5 -> 0 | AM5: =SUMIF($BC$1:$CI$1,AM$1,$BC5:$CI5)+AL5 -> 0 | AO5: =SUMIF($BC$1:$CI$1,AO$1,$BC5:$CI5)+AN5 -> 0 | AP5: =CK5 -> 0 | AT5: =AE5+AG5+AI5+AK5+AM5+AO5+SUM(AQ5:AS5) -> 0 | AZ5: =VLOOKUP(C5,Employees!D:I,5,FALSE) -> #N/A | BA5: =IF(ISBLANK(D5),0,(E5-D5)*24) -> 0 | BB5: =IF(BA5>$AY$1,1,IF(BA5>=$AX$1,0.5,0)) -> 0 | BC5: =BA5-BB5-BD5-BE5 -> 0 | BD5: =IF(AND(E5>$AV$1, D5<$AW$1),(MIN(E5,$AW$1)-MAX(D5,$AV$1))*24,0) -> 0 | BE5: =IF(E5>$AW$1,(E5-MAX(D5,$AW$1))*24,0) -> 0 | BF5: =IF(ISBLANK(G5),0,(H5-G5)*24) -> 0 | BG5: =IF(BF5>$AY$1,1,IF(BF5>=$AX$1,0.5,0)) -> 0 | BH5: =BF5-BG5-BI5-BJ5 -> 0 | BI5: =IF(AND(H5>$AV$1,G5<$AW$1),(MIN(H5,$AW$1)-MAX(G5,$AV$1))*24,0) -> 0 | BJ5: =IF(H5>$AW$1,(H5-MAX(G5,$AW$1))*24,0) -> 0 | BK5: =IF(ISBLANK(J5),0,(K5-J5)*24) -> 0 | BL5: =IF(BK5>$AY$1,1,IF(BK5>=$AX$1,0.5,0)) -> 0 | BM5: =BK5-BL5-BN5-BO5 -> 0 | BN5: =IF(AND(K5>$AV$1, J5<$AW$1),(MIN(K5,$AW$1)-MAX(J5,$AV$1))*24,0) -> 0 | BO5: =IF(K5>$AW$1,(K5-MAX(J5,$AW$1))*24,0) -> 0 | BP5: =IF(ISBLANK(M5),0,(N5-M5)*24) -> 0 | BQ5: =IF(BP5>$AY$1,1,IF(BP5>=$AX$1,0.5,0)) -> 0 | BR5: =BP5-BQ5-BS5-BT5 -> 0 | BS5: =IF(AND(N5>$AV$1, M5<$AW$1),(MIN(N5,$AW$1)-MAX(M5,$AV$1))*24,0) -> 0 | BT5: =IF(N5>$AW$1,(N5-MAX(M5,$AW$1))*24,0) -> 0 | BU5: =IF(ISBLANK(P5),0,(Q5-P5)*24) -> 0 | BV5: =IF(BU5>$AY$1,1,IF(BU5>=$AX$1,0.5,0)) -> 0 | BW5: =BU5-BV5-BX5-BY5 -> 0 | BX5: =IF(AND(Q5>$AV$1, P5<$AW$1),(MIN(Q5,$AW$1)-MAX(P5,$AV$1))*24,0) -> 0 | BY5: =IF(Q5>$AW$1,(Q5-MAX(P5,$AW$1))*24,0) -> 0 | BZ5: =IF(ISBLANK(S5),0,(T5-S5)*24) -> 0 | CA5: =IF(BZ5>$AY$1,1,IF(BZ5>=$AX$1,0.5,0)) -> 0 | CB5: =BZ5-CA5-CC5-CD5 -> 0 | CC5: =IF(AND(T5>$AV$1, S5<$AW$1),(MIN(T5,$AW$1)-MAX(S5,$AV$1))*24,0) -> 0 | CD5: =IF(T5>$AW$1,(T5-MAX(S5,$AW$1))*24,0) -> 0 | CE5: =IF(ISBLANK(V5),0,(W5-V5)*24) -> 0 | CF5: =IF(CE5>$AY$1,1,IF(CE5>=$AX$1,0.5,0)) -> 0 | CG5: =CE5-CF5-CH5-CI5 -> 0 | CH5: =IF(AND(W5>$AV$1, V5<$AW$1),(MIN(W5,$AW$1)-MAX(V5,$AV$1))*24,0) -> 0 | CI5: =IF(W5>$AW$1,(W5-MAX(V5,$AW$1))*24,0) -> 0 | CK5: =SUM(IF(F5>0,1,0),IF(I5>0,1,0),IF(L5>0,1,0),IF(O5>0,1,0),IF(R5>0,1,0),IF(U5>0,1,0),IF(X5>0,1,0)) -> 0
A6: =IF(ISNA(AZ6),"",AZ6) | F6: =BA6-BB6 -> 0 | I6: =BF6-BG6 -> 0 | L6: =BK6-BL6 -> 0 | O6: =BP6-BQ6 -> 0 | R6: =BU6-BV6 -> 0 | U6: =BZ6-CA6 -> 0 | X6: =CE6-CF6 -> 0 | AB6: =SUM(F6,I6,L6,O6,R6,U6,X6) -> 0 | AE6: =SUMIF($BC$1:$CI$1,AE$1,$BC6:$CI6)+AD6 -> 0 | AG6: =SUMIF($BC$1:$CI$1,AG$1,$BC6:$CI6)+AF6 -> 0 | AI6: =SUMIF($BC$1:$CI$1,AI$1,$BC6:$CI6)+AH6 -> 0 | AK6: =SUMIF($BC$1:$CI$1,AK$1,$BC6:$CI6)+AJ6 -> 0 | AM6: =SUMIF($BC$1:$CI$1,AM$1,$BC6:$CI6)+AL6 -> 0 | AO6: =SUMIF($BC$1:$CI$1,AO$1,$BC6:$CI6)+AN6 -> 0 | AP6: =CK6 -> 0 | AT6: =AE6+AG6+AI6+AK6+AM6+AO6+SUM(AQ6:AS6) -> 0 | AZ6: =VLOOKUP(C6,Employees!D:I,5,FALSE) -> #N/A | BA6: =IF(ISBLANK(D6),0,(E6-D6)*24) -> 0 | BB6: =IF(BA6>$AY$1,1,IF(BA6>=$AX$1,0.5,0)) -> 0 | BC6: =BA6-BB6-BD6-BE6 -> 0 | BD6: =IF(AND(E6>$AV$1, D6<$AW$1),(MIN(E6,$AW$1)-MAX(D6,$AV$1))*24,0) -> 0 | BE6: =IF(E6>$AW$1,(E6-MAX(D6,$AW$1))*24,0) -> 0 | BF6: =IF(ISBLANK(G6),0,(H6-G6)*24) -> 0 | BG6: =IF(BF6>$AY$1,1,IF(BF6>=$AX$1,0.5,0)) -> 0 | BH6: =BF6-BG6-BI6-BJ6 -> 0 | BI6: =IF(AND(H6>$AV$1,G6<$AW$1),(MIN(H6,$AW$1)-MAX(G6,$AV$1))*24,0) -> 0 | BJ6: =IF(H6>$AW$1,(H6-MAX(G6,$AW$1))*24,0) -> 0 | BK6: =IF(ISBLANK(J6),0,(K6-J6)*24) -> 0 | BL6: =IF(BK6>$AY$1,1,IF(BK6>=$AX$1,0.5,0)) -> 0 | BM6: =BK6-BL6-BN6-BO6 -> 0 | BN6: =IF(AND(K6>$AV$1, J6<$AW$1),(MIN(K6,$AW$1)-MAX(J6,$AV$1))*24,0) -> 0 | BO6: =IF(K6>$AW$1,(K6-MAX(J6,$AW$1))*24,0) -> 0 | BP6: =IF(ISBLANK(M6),0,(N6-M6)*24) -> 0 | BQ6: =IF(BP6>$AY$1,1,IF(BP6>=$AX$1,0.5,0)) -> 0 | BR6: =BP6-BQ6-BS6-BT6 -> 0 | BS6: =IF(AND(N6>$AV$1, M6<$AW$1),(MIN(N6,$AW$1)-MAX(M6,$AV$1))*24,0) -> 0 | BT6: =IF(N6>$AW$1,(N6-MAX(M6,$AW$1))*24,0) -> 0 | BU6: =IF(ISBLANK(P6),0,(Q6-P6)*24) -> 0 | BV6: =IF(BU6>$AY$1,1,IF(BU6>=$AX$1,0.5,0)) -> 0 | BW6: =BU6-BV6-BX6-BY6 -> 0 | BX6: =IF(AND(Q6>$AV$1, P6<$AW$1),(MIN(Q6,$AW$1)-MAX(P6,$AV$1))*24,0) -> 0 | BY6: =IF(Q6>$AW$1,(Q6-MAX(P6,$AW$1))*24,0) -> 0 | BZ6: =IF(ISBLANK(S6),0,(T6-S6)*24) -> 0 | CA6: =IF(BZ6>$AY$1,1,IF(BZ6>=$AX$1,0.5,0)) -> 0 | CB6: =BZ6-CA6-CC6-CD6 -> 0 | CC6: =IF(AND(T6>$AV$1, S6<$AW$1),(MIN(T6,$AW$1)-MAX(S6,$AV$1))*24,0) -> 0 | CD6: =IF(T6>$AW$1,(T6-MAX(S6,$AW$1))*24,0) -> 0 | CE6: =IF(ISBLANK(V6),0,(W6-V6)*24) -> 0 | CF6: =IF(CE6>$AY$1,1,IF(CE6>=$AX$1,0.5,0)) -> 0 | CG6: =CE6-CF6-CH6-CI6 -> 0 | CH6: =IF(AND(W6>$AV$1, V6<$AW$1),(MIN(W6,$AW$1)-MAX(V6,$AV$1))*24,0) -> 0 | CI6: =IF(W6>$AW$1,(W6-MAX(V6,$AW$1))*24,0) -> 0 | CK6: =SUM(IF(F6>0,1,0),IF(I6>0,1,0),IF(L6>0,1,0),IF(O6>0,1,0),IF(R6>0,1,0),IF(U6>0,1,0),IF(X6>0,1,0)) -> 0
A7: =IF(ISNA(AZ7),"",AZ7) | F7: =BA7-BB7 -> 0 | I7: =BF7-BG7 -> 0 | L7: =BK7-BL7 -> 0 | O7: =BP7-BQ7 -> 0 | R7: =BU7-BV7 -> 0 | U7: =BZ7-CA7 -> 0 | X7: =CE7-CF7 -> 0 | AB7: =SUM(F7,I7,L7,O7,R7,U7,X7) -> 0 | AE7: =SUMIF($BC$1:$CI$1,AE$1,$BC7:$CI7)+AD7 -> 0 | AG7: =SUMIF($BC$1:$CI$1,AG$1,$BC7:$CI7)+AF7 -> 0 | AI7: =SUMIF($BC$1:$CI$1,AI$1,$BC7:$CI7)+AH7 -> 0 | AK7: =SUMIF($BC$1:$CI$1,AK$1,$BC7:$CI7)+AJ7 -> 0 | AM7: =SUMIF($BC$1:$CI$1,AM$1,$BC7:$CI7)+AL7 -> 0 | AO7: =SUMIF($BC$1:$CI$1,AO$1,$BC7:$CI7)+AN7 -> 0 | AP7: =CK7 -> 0 | AT7: =AE7+AG7+AI7+AK7+AM7+AO7+SUM(AQ7:AS7) -> 0 | AZ7: =VLOOKUP(C7,Employees!D:I,5,FALSE) -> #N/A | BA7: =IF(ISBLANK(D7),0,(E7-D7)*24) -> 0 | BB7: =IF(BA7>$AY$1,1,IF(BA7>=$AX$1,0.5,0)) -> 0 | BC7: =BA7-BB7-BD7-BE7 -> 0 | BD7: =IF(AND(E7>$AV$1, D7<$AW$1),(MIN(E7,$AW$1)-MAX(D7,$AV$1))*24,0) -> 0 | BE7: =IF(E7>$AW$1,(E7-MAX(D7,$AW$1))*24,0) -> 0 | BF7: =IF(ISBLANK(G7),0,(H7-G7)*24) -> 0 | BG7: =IF(BF7>$AY$1,1,IF(BF7>=$AX$1,0.5,0)) -> 0 | BH7: =BF7-BG7-BI7-BJ7 -> 0 | BI7: =IF(AND(H7>$AV$1,G7<$AW$1),(MIN(H7,$AW$1)-MAX(G7,$AV$1))*24,0) -> 0 | BJ7: =IF(H7>$AW$1,(H7-MAX(G7,$AW$1))*24,0) -> 0 | BK7: =IF(ISBLANK(J7),0,(K7-J7)*24) -> 0 | BL7: =IF(BK7>$AY$1,1,IF(BK7>=$AX$1,0.5,0)) -> 0 | BM7: =BK7-BL7-BN7-BO7 -> 0 | BN7: =IF(AND(K7>$AV$1, J7<$AW$1),(MIN(K7,$AW$1)-MAX(J7,$AV$1))*24,0) -> 0 | BO7: =IF(K7>$AW$1,(K7-MAX(J7,$AW$1))*24,0) -> 0 | BP7: =IF(ISBLANK(M7),0,(N7-M7)*24) -> 0 | BQ7: =IF(BP7>$AY$1,1,IF(BP7>=$AX$1,0.5,0)) -> 0 | BR7: =BP7-BQ7-BS7-BT7 -> 0 | BS7: =IF(AND(N7>$AV$1, M7<$AW$1),(MIN(N7,$AW$1)-MAX(M7,$AV$1))*24,0) -> 0 | BT7: =IF(N7>$AW$1,(N7-MAX(M7,$AW$1))*24,0) -> 0 | BU7: =IF(ISBLANK(P7),0,(Q7-P7)*24) -> 0 | BV7: =IF(BU7>$AY$1,1,IF(BU7>=$AX$1,0.5,0)) -> 0 | BW7: =BU7-BV7-BX7-BY7 -> 0 | BX7: =IF(AND(Q7>$AV$1, P7<$AW$1),(MIN(Q7,$AW$1)-MAX(P7,$AV$1))*24,0) -> 0 | BY7: =IF(Q7>$AW$1,(Q7-MAX(P7,$AW$1))*24,0) -> 0 | BZ7: =IF(ISBLANK(S7),0,(T7-S7)*24) -> 0 | CA7: =IF(BZ7>$AY$1,1,IF(BZ7>=$AX$1,0.5,0)) -> 0 | CB7: =BZ7-CA7-CC7-CD7 -> 0 | CC7: =IF(AND(T7>$AV$1, S7<$AW$1),(MIN(T7,$AW$1)-MAX(S7,$AV$1))*24,0) -> 0 | CD7: =IF(T7>$AW$1,(T7-MAX(S7,$AW$1))*24,0) -> 0 | CE7: =IF(ISBLANK(V7),0,(W7-V7)*24) -> 0 | CF7: =IF(CE7>$AY$1,1,IF(CE7>=$AX$1,0.5,0)) -> 0 | CG7: =CE7-CF7-CH7-CI7 -> 0 | CH7: =IF(AND(W7>$AV$1, V7<$AW$1),(MIN(W7,$AW$1)-MAX(V7,$AV$1))*24,0) -> 0 | CI7: =IF(W7>$AW$1,(W7-MAX(V7,$AW$1))*24,0) -> 0 | CK7: =SUM(IF(F7>0,1,0),IF(I7>0,1,0),IF(L7>0,1,0),IF(O7>0,1,0),IF(R7>0,1,0),IF(U7>0,1,0),IF(X7>0,1,0)) -> 0
A8: =IF(ISNA(AZ8),"",AZ8) | F8: =BA8-BB8 -> 0 | I8: =BF8-BG8 -> 0 | L8: =BK8-BL8 -> 0 | O8: =BP8-BQ8 -> 0 | R8: =BU8-BV8 -> 0 | U8: =BZ8-CA8 -> 0 | X8: =CE8-CF8 -> 0 | AB8: =SUM(F8,I8,L8,O8,R8,U8,X8) -> 0 | AE8: =SUMIF($BC$1:$CI$1,AE$1,$BC8:$CI8)+AD8 -> 0 | AG8: =SUMIF($BC$1:$CI$1,AG$1,$BC8:$CI8)+AF8 -> 0 | AI8: =SUMIF($BC$1:$CI$1,AI$1,$BC8:$CI8)+AH8 -> 0 | AK8: =SUMIF($BC$1:$CI$1,AK$1,$BC8:$CI8)+AJ8 -> 0 | AM8: =SUMIF($BC$1:$CI$1,AM$1,$BC8:$CI8)+AL8 -> 0 | AO8: =SUMIF($BC$1:$CI$1,AO$1,$BC8:$CI8)+AN8 -> 0 | AP8: =CK8 -> 0 | AT8: =AE8+AG8+AI8+AK8+AM8+AO8+SUM(AQ8:AS8) -> 0 | AZ8: =VLOOKUP(C8,Employees!D:I,5,FALSE) -> #N/A | BA8: =IF(ISBLANK(D8),0,(E8-D8)*24) -> 0 | BB8: =IF(BA8>$AY$1,1,IF(BA8>=$AX$1,0.5,0)) -> 0 | BC8: =BA8-BB8-BD8-BE8 -> 0 | BD8: =IF(AND(E8>$AV$1, D8<$AW$1),(MIN(E8,$AW$1)-MAX(D8,$AV$1))*24,0) -> 0 | BE8: =IF(E8>$AW$1,(E8-MAX(D8,$AW$1))*24,0) -> 0 | BF8: =IF(ISBLANK(G8),0,(H8-G8)*24) -> 0 | BG8: =IF(BF8>$AY$1,1,IF(BF8>=$AX$1,0.5,0)) -> 0 | BH8: =BF8-BG8-BI8-BJ8 -> 0 | BI8: =IF(AND(H8>$AV$1,G8<$AW$1),(MIN(H8,$AW$1)-MAX(G8,$AV$1))*24,0) -> 0 | BJ8: =IF(H8>$AW$1,(H8-MAX(G8,$AW$1))*24,0) -> 0 | BK8: =IF(ISBLANK(J8),0,(K8-J8)*24) -> 0 | BL8: =IF(BK8>$AY$1,1,IF(BK8>=$AX$1,0.5,0)) -> 0 | BM8: =BK8-BL8-BN8-BO8 -> 0 | BN8: =IF(AND(K8>$AV$1, J8<$AW$1),(MIN(K8,$AW$1)-MAX(J8,$AV$1))*24,0) -> 0 | BO8: =IF(K8>$AW$1,(K8-MAX(J8,$AW$1))*24,0) -> 0 | BP8: =IF(ISBLANK(M8),0,(N8-M8)*24) -> 0 | BQ8: =IF(BP8>$AY$1,1,IF(BP8>=$AX$1,0.5,0)) -> 0 | BR8: =BP8-BQ8-BS8-BT8 -> 0 | BS8: =IF(AND(N8>$AV$1, M8<$AW$1),(MIN(N8,$AW$1)-MAX(M8,$AV$1))*24,0) -> 0 | BT8: =IF(N8>$AW$1,(N8-MAX(M8,$AW$1))*24,0) -> 0 | BU8: =IF(ISBLANK(P8),0,(Q8-P8)*24) -> 0 | BV8: =IF(BU8>$AY$1,1,IF(BU8>=$AX$1,0.5,0)) -> 0 | BW8: =BU8-BV8-BX8-BY8 -> 0 | BX8: =IF(AND(Q8>$AV$1, P8<$AW$1),(MIN(Q8,$AW$1)-MAX(P8,$AV$1))*24,0) -> 0 | BY8: =IF(Q8>$AW$1,(Q8-MAX(P8,$AW$1))*24,0) -> 0 | BZ8: =IF(ISBLANK(S8),0,(T8-S8)*24) -> 0 | CA8: =IF(BZ8>$AY$1,1,IF(BZ8>=$AX$1,0.5,0)) -> 0 | CB8: =BZ8-CA8-CC8-CD8 -> 0 | CC8: =IF(AND(T8>$AV$1, S8<$AW$1),(MIN(T8,$AW$1)-MAX(S8,$AV$1))*24,0) -> 0 | CD8: =IF(T8>$AW$1,(T8-MAX(S8,$AW$1))*24,0) -> 0 | CE8: =IF(ISBLANK(V8),0,(W8-V8)*24) -> 0 | CF8: =IF(CE8>$AY$1,1,IF(CE8>=$AX$1,0.5,0)) -> 0 | CG8: =CE8-CF8-CH8-CI8 -> 0 | CH8: =IF(AND(W8>$AV$1, V8<$AW$1),(MIN(W8,$AW$1)-MAX(V8,$AV$1))*24,0) -> 0 | CI8: =IF(W8>$AW$1,(W8-MAX(V8,$AW$1))*24,0) -> 0 | CK8: =SUM(IF(F8>0,1,0),IF(I8>0,1,0),IF(L8>0,1,0),IF(O8>0,1,0),IF(R8>0,1,0),IF(U8>0,1,0),IF(X8>0,1,0)) -> 0
